Workbook

Sheet NOMINA EMPELADOS CDO
D2: COMERCIALIZADORA CASA DULCE ORIENTE, C.A RIF: J-50223534-5
C5: MES DE ABRIL 2026
C6: DESDE EL 01/04 AL 30/04/2026 | AF6: TASA AL 31-03-2026
B7: NOMINA DE EMPLEADOS COMERCIALIZADORA CASA DULCE ORIENTE, C.A | AF7: 487.1192
B9: COD | C9: NOMBRE Y APELLIDOS | D9: CEDULA | E9: RIF | F9: FECHA DE INGRESO | G9: CARGO | H9: DEPARTAMENTO | I9: DIAS TRABAJ. | J9: SALARIO | K9: SALARIO MENSUAL | L9: RETROACTIVO 15-06-2018 | M9: TOTAL SALARIO MENSUAL | N9: SALARIO COMPLEMENTARIO | O9: BONO DE GUERRA COMPLEMENTARIO | P9: REEMB. | Q9: RETROACTIVO POR AJUSTE DE SALARIO A PARTIR DEL 16-04-2019 | R9: (HORAS) TIEMPO DE VIAJE | S9: PAGO TIEMPO DE VIAJE | T9: TOTAL DEVENGADO | U9: DEDUCCIONES | AC9: TOTAL PAGADO
M10: GANADO | U10: SEGURO SOCIAL | V10: PARO FORSOZO | W10: AHORRO HAB. | X10: I.S.L.R | Y10: DESC. POR PRESTAMOS (1) | Z10: DESC. POR PRESTAMOS (2) | AA10: OTRAS | AB10: TOTAL DEDUCCIONES
B11: 1 | C11: DAIRILYS DEL CARMEN GUAREGUA CHAGUAN | D11: 16067033 | E11: V-16067033-5 | F11: 45001 | G11: ENCARGADA DE TIENDA | H11: ADMINISTRACION | I11: =ASISTENCIA!AA13 -> 30 | J11: 43.333333 | K11: =J11*30 -> 1300 | M11: =I11*J11 -> 1300 | N11: =130*AF7 -> 63325.496 | O11: =(20*AF7)-M11 -> 8442.384 | P11: 0 | R11: =ASISTENCIA!Z13 -> 0 | S11: =J11/8*R11 -> 0 | T11: =M11+N11+O11 -> 73067.88 | U11: =((J11*30*12)/52*4%*4)/2 -> 24 | V11: =(J11*30*12)/52*0.5%*4 -> 6 | W11: =T11*1% -> 730.6788 | X11: =+T11*1.33% -> 971.8028 | Y11: 0 | Z11: 0 | AA11: 0 | AB11: =U11+V11+W11+X11 -> 1732.4816 | AC11: =T11-AB11 -> 71335.398
B12: =+B11+1 -> 2 | C12: EMILIO JOSÉ PINTO DOMIGUEZ | D12: 8326409 | E12: V-08326409-4 | F12: 45001 | G12: LOGISTICA | H12: OPERACIONES | I12: =ASISTENCIA!AA14 -> 30 | J12: =1300/30 -> 43.333333 | K12: =J12*30 -> 1300 | M12: =I12*J12 -> 1300 | N12: =130*AF7 -> 63325.496 | O12: =(20*AF7)-M12 -> 8442.384 | P12: =AG12 -> 0 | R12: =ASISTENCIA!Z14 -> 0 | S12: =J12/8*R12 -> 0 | T12: =M12+N12+O12 -> 73067.88 | U12: =((J12*30*12)/52*4%*4)/2 -> 24 | V12: =(J12*30*12)/52*0.5%*4 -> 6 | W12: =T12*1% -> 730.6788 | X12: =1.04%*T12 -> 759.90595 | Y12: 0 | Z12: 0 | AA12: 0 | AB12: =U12+V12+W12+X12 -> 1520.5848 | AC12: =T12-AB12 -> 71547.295
B13: =+B12+1 -> 3 | C13: JESÚS RAFAEL ARAY CAGUANA | D13: 8234036 | E13: V-08234036-6 | F13: 45218 | G13: LOGISTICA | H13: OPERACIONES | I13: =ASISTENCIA!AA15 -> 30 | J13: =1300/30 -> 43.333333 | K13: =J13*30 -> 1300 | M13: =I13*J13 -> 1300 | N13: =130*AF7 -> 63325.496 | O13: =(20*AF7)-M13 -> 8442.384 | T13: =M13+N13+O13 -> 73067.88 | U13: =((J13*30*12)/52*4%*4)/2 -> 24 | V13: =(J13*30*12)/52*0.5%*4 -> 6 | W13: =T13*1% -> 730.6788 | X13: =+T13*1.72% -> 1256.7675 | AB13: =U13+V13+W13+X13 -> 2017.4463 | AC13: =T13-AB13 -> 71050.434
B14: =+B13+1 -> 4 | C14: THEISY DEL CARMEN NADALES LOPEZ | D14: 19316663 | E14: V-19316663-2 | F14: 45839 | G14: ASESORA DE VENTAS | H14: ATENCION AL CLIENTE | I14: =ASISTENCIA!AA16 -> 30 | J14: =1300/30 -> 43.333333 | K14: =J14*30 -> 1300 | M14: =I14*J14 -> 1300 | N14: =130*AF7 -> 63325.496 | O14: =(20*AF7)-M14 -> 8442.384 | T14: =M14+N14+O14 -> 73067.88 | U14: =((J14*30*12)/52*4%*4)/2 -> 24 | V14: =(J14*30*12)/52*0.5%*4 -> 6 | W14: =T14*1% -> 730.6788 | X14: =+T14*1.3% -> 949.88244 | AB14: =U14+V14+W14+X14 -> 1710.5612 | AC14: =T14-AB14 -> 71357.319
B15: =+B14+1 -> 5 | C15: MARIA VICTORIA GUAITA CANELON | D15: 31311552 | E15: V-31311552-2 | F15: 45839 | G15: CAJERA | H15: ATENCION AL CLIENTE | I15: =ASISTENCIA!AA17 -> 30 | J15: =1300/30 -> 43.333333 | K15: =J15*30 -> 1300 | M15: =I15*J15 -> 1300 | N15: =130*AF7 -> 63325.496 | O15: =+(20*AF7)-M15 -> 8442.384 | P15: =AG15 -> 0 | R15: =ASISTENCIA!Z15 -> 0 | S15: =J15/8*R15 -> 0 | T15: =M15+N15+O15 -> 73067.88 | U15: =((J15*30*12)/52*4%*4)/2 -> 24 | V15: =(J15*30*12)/52*0.5%*4 -> 6 | W15: =T15*1% -> 730.6788 | X15: =+T15*1.67% -> 1220.2336 | Y15: 0 | Z15: 0 | AA15: 0 | AB15: =U15+V15+W15+X15 -> 1980.9124 | AC15: =T15-AB15 -> 71086.968
J16: =SUM(J11:J15) -> 216.66667 | K16: =SUM(K11:K15) -> 6500 | L16: =SUM(L11:L15) -> 0 | M16: =SUM(M11:M15) -> 6500 | N16: =SUM(N11:N15) -> 316627.48 | O16: =SUM(O11:O15) -> 42211.92 | P16: =SUM(P11:P12) -> 0 | Q16: =SUM(Q11:Q12) -> 0 | R16: =SUM(R11:R12) -> 0 | S16: =SUM(S11:S12) -> 0 | T16: =SUM(T11:T15) -> 365339.4 | U16: =SUM(U11:U15) -> 120 | V16: =SUM(V11:V15) -> 30 | W16: =SUM(W11:W15) -> 3653.394 | X16: =SUM(X11:X15) -> 5158.5923 | Y16: =SUM(Y11:Y12) -> 0 | Z16: =SUM(Z11:Z12) -> 0 | AA16: =SUM(AA11:AA12) -> 0 | AB16: =SUM(AB11:AB15) -> 8961.9863 | AC16: =SUM(AC11:AC15) -> 356377.41
H19: EMPLEADOS | I19: HRS | J19: FERIADO | M19: HRS | O19: SABADO | P19: HRS | Q19: S.D 24/06/2015 | R19: HRS | S19: S.N | T19: RECARG. DOM. | U19: TOTAL HRS. | V19: TOTAL SOBRE-TIEMPO
H20: =C11 -> DAIRILYS DEL CARMEN GUAREGUA CHAGUAN | J20: =((J11)+(115%*J11))/8*I20 -> 0 | M20: 0 | O20: =((J11)+(115%*J11))/8*M20 -> 0 | P20: 0 | Q20: =(J11/8*(90/100)+(J11/8))*P20 -> 0 | R20: 0 | S20: =(J11/8*(115/100)+(J11/8))*R20 -> 0 | T20: =(J20+O20+Q20+S20)/7 -> 0 | U20: =I20+M20+P20+R20 -> 0 | V20: =J20+O20+Q20+S20+T20 -> 0 | AC20: =73067.88*5 -> 365339.4
H21: =C12 -> EMILIO JOSÉ PINTO DOMIGUEZ | J21: =((J12)+(115%*J12))/8*I21 -> 0 | M21: 0 | O21: =((J12)+(115%*J12))/8*M21 -> 0 | P21: 0 | Q21: =(J12/8*(90/100)+(J12/8))*P21 -> 0 | R21: 0 | S21: =(J12/8*(115/100)+(J12/8))*R21 -> 0 | T21: =(J21+O21+Q21+S21)/7 -> 0 | U21: =I21+M21+P21+R21 -> 0 | V21: =J21+O21+Q21+S21+T21 -> 0 | AC21: =146135.76*2 -> 292271.52
H22: =C13 -> JESÚS RAFAEL ARAY CAGUANA | J22: =((J13)+(115%*J13))/8*I22 -> 0 | M22: 0 | O22: =((J13)+(115%*J13))/8*M22 -> 0 | P22: 0 | Q22: =(J13/8*(90/100)+(J13/8))*P22 -> 0 | R22: 0 | S22: =(J13/8*(115/100)+(J13/8))*R22 -> 0 | T22: =(J22+O22+Q22+S22)/7 -> 0 | U22: =I22+M22+P22+R22 -> 0 | V22: =J22+O22+Q22+S22+T22 -> 0 | AC22: =+AC20+AC21 -> 657610.92
H23: =C14 -> THEISY DEL CARMEN NADALES LOPEZ | J23: =((J14)+(115%*J14))/8*I23 -> 0 | M23: 0 | O23: =((J14)+(115%*J14))/8*M23 -> 0 | P23: 0 | Q23: =(J14/8*(90/100)+(J14/8))*P23 -> 0 | R23: 0 | S23: =(J14/8*(115/100)+(J14/8))*R23 -> 0 | T23: =(J23+O23+Q23+S23)/7 -> 0 | U23: =I23+M23+P23+R23 -> 0 | V23: =J23+O23+Q23+S23+T23 -> 0 | AC23: =876814.57-AC22 -> 219203.65
H24: =C15 -> MARIA VICTORIA GUAITA CANELON | J24: =((J15)+(115%*J15))/8*I24 -> 0 | M24: 0 | O24: =((J15)+(115%*J15))/8*M24 -> 0 | P24: 0 | Q24: =(J15/8*(90/100)+(J15/8))*P24 -> 0 | R24: 0 | S24: =(J15/8*(115/100)+(J15/8))*R24 -> 0 | T24: =(J24+O24+Q24+S24)/7 -> 0 | U24: =I24+M24+P24+R24 -> 0 | V24: =J24+O24+Q24+S24+T24 -> 0
H25: =C16 -> 0 | J25: =((J16)+(115%*J16))/8*I25 -> 0 | M25: 0 | O25: =((J16)+(115%*J16))/8*M25 -> 0 | P25: 0 | Q25: =(J16/8*(90/100)+(J16/8))*P25 -> 0 | R25: 0 | S25: =(J16/8*(115/100)+(J16/8))*R25 -> 0 | T25: =(J25+O25+Q25+S25)/7 -> 0 | U25: =I25+M25+P25+R25 -> 0 | V25: =J25+O25+Q25+S25+T25 -> 0
I26: =SUM(I20:I21) -> 0 | J26: =SUM(J20:J21) -> 0 | M26: =SUM(M20:M21) -> 0 | O26: =SUM(O20:O21) -> 0 | P26: =SUM(P20:P21) -> 0 | Q26: =SUM(Q20:Q21) -> 0 | R26: =SUM(R20:R21) -> 0 | S26: =SUM(S20:S21) -> 0 | T26: =SUM(T20:T21) -> 0 | U26: =SUM(U20:U21) -> 0 | V26: =SUM(V20:V21) -> 0

Sheet NOMINA DIRECTIVOS
D2: COMERCIALIZADORA CASA DULCE ORIENTE, C.A RIF: J-50223534-5
C5: ='NOMINA EMPELADOS CDO'!C5 -> MES DE ABRIL 2026
C6: ='NOMINA EMPELADOS CDO'!C6 -> DESDE EL 01/04 AL 30/04/2026 | AD6: ='NOMINA EMPELADOS CDO'!AF6 -> TASA AL 31-03-2026
B7: NOMINA DE EMPLEADOS COMERCIALIZADORA CASA DULCE ORIENTE, C.A | AD7: ='NOMINA EMPELADOS CDO'!AF7 -> 487.1192
B9: COD | C9: NOMBRE Y APELLIDOS | D9: CEDULA | E9: RIF | F9: FECHA DE INGRESO | G9: CARGO | H9: DEPARTAMENTO | I9: DIAS TRABAJ. | J9: SALARIO | K9: SALARIO MENSUAL | L9: RETROACTIVO 15-06-2018 | M9: TOTAL SALARIO MENSUAL | N9: BONO COMPLEMENTARIO | O9: REEMB. | P9: RETROACTIVO POR AJUSTE DE SALARIO A PARTIR DEL 16-04-2019 | Q9: (HORAS) TIEMPO DE VIAJE | R9: PAGO TIEMPO DE VIAJE | S9: TOTAL DEVENGADO | T9: DEDUCCIONES | AB9: TOTAL PAGADO | AD9: =300*AD7 -> 146135.76
M10: GANADO | T10: SEGURO SOCIAL | U10: PARO FORSOZO | V10: AHORRO HAB. | W10: I.S.L.R | X10: DESC. POR PRESTAMOS (1) | Y10: DESC. POR PRESTAMOS (2) | Z10: OTRAS | AA10: TOTAL DEDUCCIONES
B11: D-1 | C11: ELIAS ANTONIO NAYATI VARGAS | D11: 15514275 | E11: V-15514275-4 | F11: 45219 | G11: PRESIDENTE | H11: PRESIDENCIA | I11: =ASISTENCIA!AA13 -> 30 | J11: =(300*AD7)/30 -> 4871.192 | K11: =J11*30 -> 146135.76 | L11: 0 | M11: =I11*J11 -> 146135.76 | N11: 0 | O11: 0 | Q11: =ASISTENCIA!Z13 -> 0 | R11: =J11/8*Q11 -> 0 | S11: =M11+N11 -> 146135.76 | T11: 0 | U11: 0 | V11: 0 | W11: =S11*2.63% -> 3843.3705 | X11: 0 | Y11: 0 | Z11: 0 | AA11: =T11+U11+V11+W11 -> 3843.3705 | AB11: =S11-AA11 -> 142292.39 | AD11: 3313.6998
B12: D-2 | C12: KARELIS ADREINA ESPLUGUEZ SARMIENTO | D12: 16489561 | E12: V-16489561-7 | F12: 45219 | G12: VICEPRESIDENTE | H12: PRESIDENCIA | I12: =ASISTENCIA!AA14 -> 30 | J12: =(300*AD7)/30 -> 4871.192 | K12: =J12*30 -> 146135.76 | L12: 0 | M12: =I12*J12 -> 146135.76 | N12: 0 | O12: =AE12 -> 0 | Q12: =ASISTENCIA!Z14 -> 0 | R12: =J12/8*Q12 -> 0 | S12: =M12+N12 -> 146135.76 | T12: 0 | U12: 0 | V12: 0 | W12: =+S12*2.34% -> 3419.5768 | X12: 0 | Y12: 0 | Z12: 0 | AA12: =T12+U12+V12+W12 -> 3419.5768 | AB12: =S12-AA12 -> 142716.18 | AD12: 2948.3108
J13: =SUM(J11:J12) -> 9742.384 | K13: =SUM(K11:K12) -> 292271.52 | L13: =SUM(L11:L12) -> 0 | M13: =SUM(M11:M12) -> 292271.52 | N13: =SUM(N11:N12) -> 0 | O13: =SUM(O11:O12) -> 0 | P13: =SUM(P11:P12) -> 0 | Q13: =SUM(Q11:Q12) -> 0 | ... AB13: =SUM(AB11:AB12) -> 285008.57 | AD13: 340.6
H16: DIRECTIVOS | I16: HRS | J16: FERIADO | M16: HRS | N16: SABADO | O16: HRS | P16: S.D 24/06/2015 | Q16: HRS | R16: S.N | S16: RECARG. DOM. | T16: TOTAL HRS. | U16: TOTAL SOBRE-TIEMPO
H17: =C11 -> ELIAS ANTONIO NAYATI VARGAS | J17: =((J11)+(115%*J11))/8*I17 -> 0 | M17: 0 | N17: =((J11)+(115%*J11))/8*M17 -> 0 | O17: 0 | P17: =(J11/8*(90/100)+(J11/8))*O17 -> 0 | Q17: 0 | R17: =(J11/8*(115/100)+(J11/8))*Q17 -> 0 | S17: =(J17+N17+P17+R17)/7 -> 0 | T17: =I17+M17+O17+Q17 -> 0 | U17: =J17+N17+P17+R17+S17 -> 0
H18: =C12 -> KARELIS ADREINA ESPLUGUEZ SARMIENTO | J18: =((J12)+(115%*J12))/8*I18 -> 0 | M18: 0 | N18: =((J12)+(115%*J12))/8*M18 -> 0 | O18: 0 | P18: =(J12/8*(90/100)+(J12/8))*O18 -> 0 | Q18: 0 | R18: =(J12/8*(115/100)+(J12/8))*Q18 -> 0 | S18: =(J18+N18+P18+R18)/7 -> 0 | T18: =I18+M18+O18+Q18 -> 0 | U18: =J18+N18+P18+R18+S18 -> 0
H19: =C13 -> 0 | J19: =((J13)+(115%*J13))/8*I19 -> 0 | M19: 0 | N19: =((J13)+(115%*J13))/8*M19 -> 0 | O19: 0 | P19: =(J13/8*(90/100)+(J13/8))*O19 -> 0 | Q19: 0 | R19: =(J13/8*(115/100)+(J13/8))*Q19 -> 0 | S19: =(J19+N19+P19+R19)/7 -> 0 | T19: =I19+M19+O19+Q19 -> 0 | U19: =J19+N19+P19+R19+S19 -> 0
I20: =SUM(I17:I18) -> 0 | J20: =SUM(J17:J18) -> 0 | M20: =SUM(M17:M18) -> 0 | N20: =SUM(N17:N18) -> 0 | O20: =SUM(O17:O18) -> 0 | P20: =SUM(P17:P18) -> 0 | Q20: =SUM(Q17:Q18) -> 0 | R20: =SUM(R17:R18) -> 0 | S20: =SUM(S17:S18) -> 0 | T20: =SUM(T17:T18) -> 0 | U20: =SUM(U17:U18) -> 0

Sheet  1RECIBOS DEL 1 AL 2
C3: COMERCIALIZADORA CASA DULCE ORIENTE, C.A. RIF: J-50223534-5
C4: COMPROBANTE DE PAGO | K4: Nº | L4: ='NOMINA EMPELADOS CDO'!B11 -> 1
C5: ='NOMINA EMPELADOS CDO'!C6 -> DESDE EL 01/04 AL 30/04/2026
C7: NOMBRES Y APELLIDOS: | E7: ='NOMINA EMPELADOS CDO'!C11 -> DAIRILYS DEL CARMEN GUAREGUA CHAGUAN | J7: C.I.: | K7: ='NOMINA EMPELADOS CDO'!D11 -> 16067033
C8: FECHA DE INGRESO: | E8: ='NOMINA EMPELADOS CDO'!F11 -> 45001 | F8: CARGO: | G8: ='NOMINA EMPELADOS CDO'!G11 -> ENCARGADA DE TIENDA | J8: DPTO: | K8: ='NOMINA EMPELADOS CDO'!H11 -> ADMINISTRACION
C9: TOTAL DEVENGADO:
C10: DIAS | D10: ='NOMINA EMPELADOS CDO'!I11 -> 30 | E10: SALARIO DIARIO: | G10: ='NOMINA EMPELADOS CDO'!J11 -> 43.333333 | H10: Bs. | I10: =G10*D10 -> 1300 | J10: SALARIO MENSUAL: | L10: =G10*30 -> 1300
C11: H. EXTRAS DIURNAS | E11: Nº HORAS | F11: ='NOMINA EMPELADOS CDO'!P20 -> 0 | H11: Bs. | I11: ='NOMINA EMPELADOS CDO'!Q20 -> 0
C12: H EXTRAS NOCTURNAS | E12: Nº HORAS | F12: ='NOMINA EMPELADOS CDO'!R20 -> 0 | H12: Bs. | I12: ='NOMINA EMPELADOS CDO'!S20 -> 0
C13: SABADO | E13: Nº HORAS | F13: ='NOMINA EMPELADOS CDO'!M20 -> 0 | H13: Bs. | I13: ='NOMINA EMPELADOS CDO'!O20 -> 0
C14: RECARGO DOMINGO | E14: A Bs. | H14: Bs. | I14: ='NOMINA EMPELADOS CDO'!T20 -> 0
C15: FERIADO | E15: Nº HORAS | F15: ='NOMINA EMPELADOS CDO'!I20 -> 0 | H15: Bs. | I15: ='NOMINA EMPELADOS CDO'!J20 -> 0
C16: REEMBOLSO | E16: A Bs. | H16: Bs. | I16: ='NOMINA EMPELADOS CDO'!P11 -> 0
C17: TIEMPO DE VIAJE | F17: ='NOMINA EMPELADOS CDO'!R11 -> 0 | G17: HORAS | H17: Bs. | I17: ='NOMINA EMPELADOS CDO'!S11 -> 0
C18: BONO COMPLEMENTARIO | H18: Bs. | I18: =+'NOMINA EMPELADOS CDO'!O11 -> 8442.384
E19: TOTAL DEVENGADO | H19: Bs. | I19: =SUM(I10:I18) -> 9742.384
C20: TOTAL DEDUCCIONES:
C21: S.S.O. | F21: BsS. | G21: ='NOMINA EMPELADOS CDO'!U11 -> 24
C22: I.S.L.R | F22: BsS. | G22: ='NOMINA EMPELADOS CDO'!X11 -> 971.8028
C23: AHORRO HABITACIONAL | F23: BsS. | G23: ='NOMINA EMPELADOS CDO'!W11 -> 730.6788
C24: PARO FORZOSO | F24: BsS. | G24: ='NOMINA EMPELADOS CDO'!V11 -> 6
C25: DESC. POR PRESTAMOS | F25: BsS. | G25: ='NOMINA EMPELADOS CDO'!Y11 -> 0
C26: OTRAS | F26: BsS. | G26: ='NOMINA EMPELADOS CDO'!AA11 -> 0
C27: TOTAL DEDUCCIONES | F27: BsS. | G27: =SUM(G21:G26) -> 1732.4816 | H27: TOTAL RECIBIDO Bs. | K27: =I19-G27 -> 8009.9024
J29: FIRMA
J30: FIRMA
C35: =C3 -> COMERCIALIZADORA CASA DULCE ORIENTE, C.A. RIF: J-50223534-5
C36: COMPROBANTE DE PAGO | K36: Nº | L36: ='NOMINA EMPELADOS CDO'!B12 -> 2
C37: ='NOMINA EMPELADOS CDO'!C6 -> DESDE EL 01/04 AL 30/04/2026
C39: NOMBRES Y APELLIDOS: | E39: ='NOMINA EMPELADOS CDO'!C12 -> EMILIO JOSÉ PINTO DOMIGUEZ | J39: C.I.: | K39: ='NOMINA EMPELADOS CDO'!D12 -> 8326409
C40: FECHA DE INGRESO: | E40: ='NOMINA EMPELADOS CDO'!F12 -> 45001 | F40: CARGO: | G40: ='NOMINA EMPELADOS CDO'!G12 -> LOGISTICA | J40: DPTO: | K40: ='NOMINA EMPELADOS CDO'!H12 -> OPERACIONES
C41: TOTAL DEVENGADO:
C42: DIAS | D42: ='NOMINA EMPELADOS CDO'!I12 -> 30 | E42: SALARIO DIARIO: | G42: ='NOMINA EMPELADOS CDO'!J12 -> 43.333333 | H42: BsS. | I42: =G42*D42 -> 1300 | J42: SALARIO MENSUAL: | L42: =G42*30 -> 1300
C43: H. EXTRAS DIURNAS | E43: Nº HORAS | F43: ='NOMINA EMPELADOS CDO'!P21 -> 0 | H43: BsS. | I43: ='NOMINA EMPELADOS CDO'!Q21 -> 0
C44: H EXTRAS NOCTURNAS | E44: Nº HORAS | F44: ='NOMINA EMPELADOS CDO'!R21 -> 0 | H44: BsS. | I44: ='NOMINA EMPELADOS CDO'!S21 -> 0
C45: SABADO | E45: Nº HORAS | F45: ='NOMINA EMPELADOS CDO'!M21 -> 0 | H45: BsS. | I45: ='NOMINA EMPELADOS CDO'!O21 -> 0
C46: RECARGO DOMINGO | E46: A Bs. | H46: BsS. | I46: ='NOMINA EMPELADOS CDO'!T21 -> 0
C47: FERIADO | E47: Nº HORAS | F47: ='NOMINA EMPELADOS CDO'!I21 -> 0 | H47: BsS. | I47: ='NOMINA EMPELADOS CDO'!J21 -> 0
C48: REEMBOLSO | E48: A Bs. | H48: BsS. | I48: ='NOMINA EMPELADOS CDO'!P12 -> 0
C49: TIEMPO DE VIAJE | F49: ='NOMINA EMPELADOS CDO'!R12 -> 0 | G49: HORAS | H49: BsS. | I49: ='NOMINA EMPELADOS CDO'!S12 -> 0
...

Sheet  1RECIBOS DEL 3 AL 4
C3: COMERCIALIZADORA CASA DULCE ORIENTE, C.A. RIF: J-50223534-5
C4: COMPROBANTE DE PAGO | K4: Nº | L4: ='NOMINA EMPELADOS CDO'!B13 -> 3
C5: ='NOMINA EMPELADOS CDO'!C6 -> DESDE EL 01/04 AL 30/04/2026
C7: NOMBRES Y APELLIDOS: | E7: ='NOMINA EMPELADOS CDO'!C13 -> JESÚS RAFAEL ARAY CAGUANA | J7: C.I.: | K7: ='NOMINA EMPELADOS CDO'!D13 -> 8234036
C8: FECHA DE INGRESO: | E8: ='NOMINA EMPELADOS CDO'!F13 -> 45218 | F8: CARGO: | G8: ='NOMINA EMPELADOS CDO'!G13 -> LOGISTICA | J8: DPTO: | K8: ='NOMINA EMPELADOS CDO'!H13 -> OPERACIONES
C9: TOTAL DEVENGADO:
C10: DIAS | D10: ='NOMINA EMPELADOS CDO'!I13 -> 30 | E10: SALARIO DIARIO: | G10: ='NOMINA EMPELADOS CDO'!J13 -> 43.333333 | H10: Bs. | I10: =G10*D10 -> 1300 | J10: SALARIO MENSUAL: | L10: =G10*30 -> 1300
C11: H. EXTRAS DIURNAS | E11: Nº HORAS | F11: ='NOMINA EMPELADOS CDO'!P20 -> 0 | H11: Bs. | I11: ='NOMINA EMPELADOS CDO'!Q20 -> 0
C12: H EXTRAS NOCTURNAS | E12: Nº HORAS | F12: ='NOMINA EMPELADOS CDO'!R20 -> 0 | H12: Bs. | I12: ='NOMINA EMPELADOS CDO'!S20 -> 0
C13: SABADO | E13: Nº HORAS | F13: ='NOMINA EMPELADOS CDO'!M20 -> 0 | H13: Bs. | I13: ='NOMINA EMPELADOS CDO'!O20 -> 0
C14: RECARGO DOMINGO | E14: A Bs. | H14: Bs. | I14: ='NOMINA EMPELADOS CDO'!T20 -> 0
C15: FERIADO | E15: Nº HORAS | F15: ='NOMINA EMPELADOS CDO'!I20 -> 0 | H15: Bs. | I15: ='NOMINA EMPELADOS CDO'!J20 -> 0
C16: REEMBOLSO | E16: A Bs. | H16: Bs. | I16: ='NOMINA EMPELADOS CDO'!P11 -> 0
C17: TIEMPO DE VIAJE | F17: ='NOMINA EMPELADOS CDO'!R11 -> 0 | G17: HORAS | H17: Bs. | I17: ='NOMINA EMPELADOS CDO'!S11 -> 0
C18: BONO COMPLEMENTARIO | H18: Bs. | I18: =+'NOMINA EMPELADOS CDO'!O13 -> 8442.384
E19: TOTAL DEVENGADO | H19: Bs. | I19: =SUM(I10:I18) -> 9742.384
C20: TOTAL DEDUCCIONES:
C21: S.S.O. | F21: BsS. | G21: ='NOMINA EMPELADOS CDO'!U13 -> 24
C22: I.S.L.R | F22: BsS. | G22: ='NOMINA EMPELADOS CDO'!X13 -> 1256.7675
C23: AHORRO HABITACIONAL | F23: BsS. | G23: ='NOMINA EMPELADOS CDO'!W13 -> 730.6788
C24: PARO FORZOSO | F24: BsS. | G24: ='NOMINA EMPELADOS CDO'!V13 -> 6
C25: DESC. POR PRESTAMOS | F25: BsS. | G25: ='NOMINA EMPELADOS CDO'!Y11 -> 0
C26: OTRAS | F26: BsS. | G26: ='NOMINA EMPELADOS CDO'!AA11 -> 0
C27: TOTAL DEDUCCIONES | F27: BsS. | G27: =SUM(G21:G26) -> 2017.4463 | H27: TOTAL RECIBIDO Bs. | K27: =I19-G27 -> 7724.9377
J29: FIRMA
J30: FIRMA
C35: =C3 -> COMERCIALIZADORA CASA DULCE ORIENTE, C.A. RIF: J-50223534-5
C36: COMPROBANTE DE PAGO | K36: Nº | L36: ='NOMINA EMPELADOS CDO'!B14 -> 4
C37: ='NOMINA EMPELADOS CDO'!C6 -> DESDE EL 01/04 AL 30/04/2026
C39: NOMBRES Y APELLIDOS: | E39: ='NOMINA EMPELADOS CDO'!C14 -> THEISY DEL CARMEN NADALES LOPEZ | J39: C.I.: | K39: ='NOMINA EMPELADOS CDO'!D14 -> 19316663
C40: FECHA DE INGRESO: | E40: ='NOMINA EMPELADOS CDO'!F14 -> 45839 | F40: CARGO: | G40: ='NOMINA EMPELADOS CDO'!G14 -> ASESORA DE VENTAS | J40: DPTO: | K40: ='NOMINA EMPELADOS CDO'!H14 -> ATENCION AL CLIENTE
C41: TOTAL DEVENGADO:
C42: DIAS | D42: ='NOMINA EMPELADOS CDO'!I12 -> 30 | E42: SALARIO DIARIO: | G42: ='NOMINA EMPELADOS CDO'!J14 -> 43.333333 | H42: BsS. | I42: =G42*D42 -> 1300 | J42: SALARIO MENSUAL: | L42: =G42*30 -> 1300
C43: H. EXTRAS DIURNAS | E43: Nº HORAS | F43: ='NOMINA EMPELADOS CDO'!P21 -> 0 | H43: BsS. | I43: ='NOMINA EMPELADOS CDO'!Q21 -> 0
C44: H EXTRAS NOCTURNAS | E44: Nº HORAS | F44: ='NOMINA EMPELADOS CDO'!R21 -> 0 | H44: BsS. | I44: ='NOMINA EMPELADOS CDO'!S21 -> 0
C45: SABADO | E45: Nº HORAS | F45: ='NOMINA EMPELADOS CDO'!M21 -> 0 | H45: BsS. | I45: ='NOMINA EMPELADOS CDO'!O21 -> 0
C46: RECARGO DOMINGO | E46: A Bs. | H46: BsS. | I46: ='NOMINA EMPELADOS CDO'!T21 -> 0
C47: FERIADO | E47: Nº HORAS | F47: ='NOMINA EMPELADOS CDO'!I21 -> 0 | H47: BsS. | I47: ='NOMINA EMPELADOS CDO'!J21 -> 0
C48: REEMBOLSO | E48: A Bs. | H48: BsS. | I48: ='NOMINA EMPELADOS CDO'!P12 -> 0
C49: TIEMPO DE VIAJE | F49: ='NOMINA EMPELADOS CDO'!R12 -> 0 | G49: HORAS | H49: BsS. | I49: ='NOMINA EMPELADOS CDO'!S12 -> 0
...

Sheet  1RECIBOS DEL 5 AL6 
C3: COMERCIALIZADORA CASA DULCE ORIENTE, C.A. RIF: J-50223534-5
C4: COMPROBANTE DE PAGO | K4: Nº | L4: ='NOMINA EMPELADOS CDO'!B15 -> 5
C5: ='NOMINA EMPELADOS CDO'!C6 -> DESDE EL 01/04 AL 30/04/2026
C7: NOMBRES Y APELLIDOS: | E7: ='NOMINA EMPELADOS CDO'!C15 -> MARIA VICTORIA GUAITA CANELON | J7: C.I.: | K7: ='NOMINA EMPELADOS CDO'!D11 -> 16067033
C8: FECHA DE INGRESO: | E8: ='NOMINA EMPELADOS CDO'!F15 -> 45839 | F8: CARGO: | G8: ='NOMINA EMPELADOS CDO'!G15 -> CAJERA | J8: DPTO: | K8: ='NOMINA EMPELADOS CDO'!H15 -> ATENCION AL CLIENTE
C9: TOTAL DEVENGADO:
C10: DIAS | D10: ='NOMINA EMPELADOS CDO'!I15 -> 30 | E10: SALARIO DIARIO: | G10: ='NOMINA EMPELADOS CDO'!J15 -> 43.333333 | H10: Bs. | I10: =G10*D10 -> 1300 | J10: SALARIO MENSUAL: | L10: =G10*30 -> 1300
C11: H. EXTRAS DIURNAS | E11: Nº HORAS | F11: ='NOMINA EMPELADOS CDO'!P20 -> 0 | H11: Bs. | I11: ='NOMINA EMPELADOS CDO'!Q20 -> 0
C12: H EXTRAS NOCTURNAS | E12: Nº HORAS | F12: ='NOMINA EMPELADOS CDO'!R20 -> 0 | H12: Bs. | I12: ='NOMINA EMPELADOS CDO'!S20 -> 0
C13: SABADO | E13: Nº HORAS | F13: ='NOMINA EMPELADOS CDO'!M20 -> 0 | H13: Bs. | I13: ='NOMINA EMPELADOS CDO'!O20 -> 0
C14: RECARGO DOMINGO | E14: A Bs. | H14: Bs. | I14: ='NOMINA EMPELADOS CDO'!T20 -> 0
C15: FERIADO | E15: Nº HORAS | F15: ='NOMINA EMPELADOS CDO'!I20 -> 0 | H15: Bs. | I15: ='NOMINA EMPELADOS CDO'!J20 -> 0
C16: REEMBOLSO | E16: A Bs. | H16: Bs. | I16: ='NOMINA EMPELADOS CDO'!P11 -> 0
C17: TIEMPO DE VIAJE | F17: ='NOMINA EMPELADOS CDO'!R11 -> 0 | G17: HORAS | H17: Bs. | I17: ='NOMINA EMPELADOS CDO'!S11 -> 0
C18: BONO COMPLEMENTARIO | H18: Bs. | I18: =+'NOMINA EMPELADOS CDO'!O15 -> 8442.384
E19: TOTAL DEVENGADO | H19: Bs. | I19: =SUM(I10:I18) -> 9742.384
C20: TOTAL DEDUCCIONES:
C21: S.S.O. | F21: BsS. | G21: ='NOMINA EMPELADOS CDO'!U15 -> 24
C22: I.S.L.R | F22: BsS. | G22: ='NOMINA EMPELADOS CDO'!X15 -> 1220.2336
C23: AHORRO HABITACIONAL | F23: BsS. | G23: ='NOMINA EMPELADOS CDO'!W15 -> 730.6788
C24: PARO FORZOSO | F24: BsS. | G24: ='NOMINA EMPELADOS CDO'!V15 -> 6
C25: DESC. POR PRESTAMOS | F25: BsS. | G25: ='NOMINA EMPELADOS CDO'!Y15 -> 0
C26: OTRAS | F26: BsS. | G26: ='NOMINA EMPELADOS CDO'!AA15 -> 0
C27: TOTAL DEDUCCIONES | F27: BsS. | G27: =SUM(G21:G26) -> 1980.9124 | H27: TOTAL RECIBIDO Bs. | K27: =I19-G27 -> 7761.4716
J29: FIRMA
J30: FIRMA
C35: =C3 -> COMERCIALIZADORA CASA DULCE ORIENTE, C.A. RIF: J-50223534-5
C36: COMPROBANTE DE PAGO | K36: Nº | L36: ='NOMINA EMPELADOS CDO'!B12 -> 2
C37: ='NOMINA EMPELADOS CDO'!C6 -> DESDE EL 01/04 AL 30/04/2026
C39: NOMBRES Y APELLIDOS: | J39: C.I.:
C40: FECHA DE INGRESO: | E40: ='NOMINA EMPELADOS CDO'!F12 -> 45001 | F40: CARGO: | G40: ='NOMINA EMPELADOS CDO'!G12 -> LOGISTICA | J40: DPTO: | K40: ='NOMINA EMPELADOS CDO'!H12 -> OPERACIONES
C41: TOTAL DEVENGADO:
C42: DIAS | D42: ='NOMINA EMPELADOS CDO'!I12 -> 30 | E42: SALARIO DIARIO: | G42: ='NOMINA EMPELADOS CDO'!J12 -> 43.333333 | H42: BsS. | I42: =G42*D42 -> 1300 | J42: SALARIO MENSUAL: | L42: =G42*30 -> 1300
C43: H. EXTRAS DIURNAS | E43: Nº HORAS | F43: ='NOMINA EMPELADOS CDO'!P21 -> 0 | H43: BsS. | I43: ='NOMINA EMPELADOS CDO'!Q21 -> 0
C44: H EXTRAS NOCTURNAS | E44: Nº HORAS | F44: ='NOMINA EMPELADOS CDO'!R21 -> 0 | H44: BsS. | I44: ='NOMINA EMPELADOS CDO'!S21 -> 0
C45: SABADO | E45: Nº HORAS | F45: ='NOMINA EMPELADOS CDO'!M21 -> 0 | H45: BsS. | I45: ='NOMINA EMPELADOS CDO'!O21 -> 0
C46: RECARGO DOMINGO | E46: A Bs. | H46: BsS. | I46: ='NOMINA EMPELADOS CDO'!T21 -> 0
C47: FERIADO | E47: Nº HORAS | F47: ='NOMINA EMPELADOS CDO'!I21 -> 0 | H47: BsS. | I47: ='NOMINA EMPELADOS CDO'!J21 -> 0
C48: REEMBOLSO | E48: A Bs. | H48: BsS. | I48: ='NOMINA EMPELADOS CDO'!P12 -> 0
C49: TIEMPO DE VIAJE | F49: ='NOMINA EMPELADOS CDO'!R12 -> 0 | G49: HORAS | H49: BsS. | I49: ='NOMINA EMPELADOS CDO'!S12 -> 0
...

Sheet  1RECIBOS DEL D-1 Y D-2
C3: COMERCIALIZADORA CASA DULCE ORIENTE, C.A. RIF: J-50223534-5
C4: COMPROBANTE DE PAGO | K4: Nº | L4: =+'NOMINA DIRECTIVOS'!B11 -> D-1
C5: =+'NOMINA DIRECTIVOS'!C6:F6 -> DESDE EL 01/04 AL 30/04/2026
C7: NOMBRES Y APELLIDOS: | E7: =+'NOMINA DIRECTIVOS'!C11 -> ELIAS ANTONIO NAYATI VARGAS | J7: C.I.: | K7: ='NOMINA DIRECTIVOS'!D11 -> 15514275
C8: FECHA DE INGRESO: | E8: =+'NOMINA DIRECTIVOS'!F11 -> 45219 | F8: CARGO: | G8: ='NOMINA DIRECTIVOS'!G11 -> PRESIDENTE | J8: DPTO: | K8: ='NOMINA DIRECTIVOS'!H11 -> PRESIDENCIA
C9: TOTAL DEVENGADO:
C10: DIAS | D10: ='NOMINA DIRECTIVOS'!I11 -> 30 | E10: SALARIO DIARIO: | G10: =+'NOMINA DIRECTIVOS'!J11 -> 4871.192 | H10: Bs. | I10: =G10*D10 -> 146135.76 | J10: SALARIO MENSUAL: | L10: =G10*30 -> 146135.76
C11: H. EXTRAS DIURNAS | E11: Nº HORAS | F11: ='NOMINA DIRECTIVOS'!O20 -> 0 | H11: Bs. | I11: ='NOMINA EMPELADOS CDO'!Q20 -> 0
C12: H EXTRAS NOCTURNAS | E12: Nº HORAS | F12: ='NOMINA DIRECTIVOS'!O21 -> 0 | H12: Bs. | I12: ='NOMINA EMPELADOS CDO'!S20 -> 0
C13: SABADO | E13: Nº HORAS | F13: ='NOMINA DIRECTIVOS'!O22 -> 0 | H13: Bs. | I13: ='NOMINA EMPELADOS CDO'!O20 -> 0
C14: RECARGO DOMINGO | E14: A Bs. | H14: Bs. | I14: ='NOMINA EMPELADOS CDO'!T20 -> 0
C15: FERIADO | E15: Nº HORAS | F15: ='NOMINA DIRECTIVOS'!I20 -> 0 | H15: Bs. | I15: ='NOMINA EMPELADOS CDO'!J20 -> 0
C16: REEMBOLSO | E16: A Bs. | H16: Bs. | I16: ='NOMINA EMPELADOS CDO'!P11 -> 0
C17: TIEMPO DE VIAJE | F17: ='NOMINA DIRECTIVOS'!Q11 -> 0 | G17: HORAS | H17: Bs. | I17: ='NOMINA EMPELADOS CDO'!S11 -> 0
C18: BONO COMPLEMENTARIO | H18: Bs. | I18: ='NOMINA DIRECTIVOS'!N11 -> 0
E19: TOTAL DEVENGADO | H19: Bs. | I19: =SUM(I10:I18) -> 146135.76
C20: TOTAL DEDUCCIONES:
C21: S.S.O. | F21: BsS. | G21: ='NOMINA DIRECTIVOS'!T11 -> 0
C22: I.S.L.R | F22: BsS. | G22: =+'NOMINA DIRECTIVOS'!W11 -> 3843.3705
C23: AHORRO HABITACIONAL | F23: BsS. | G23: ='NOMINA DIRECTIVOS'!V11 -> 0
C24: PARO FORZOSO | F24: BsS. | G24: ='NOMINA DIRECTIVOS'!U11 -> 0
C25: DESC. POR PRESTAMOS | F25: BsS. | G25: 0
C26: OTRAS | F26: BsS. | G26: 0
C27: TOTAL DEDUCCIONES | F27: BsS. | G27: =SUM(G21:G26) -> 3843.3705 | H27: TOTAL RECIBIDO Bs. | K27: =I19-G27 -> 142292.39
J29: FIRMA
J30: FIRMA
C35: =C3 -> COMERCIALIZADORA CASA DULCE ORIENTE, C.A. RIF: J-50223534-5
C36: COMPROBANTE DE PAGO | K36: Nº | L36: ='NOMINA DIRECTIVOS'!B12 -> D-2
C37: ='NOMINA EMPELADOS CDO'!C6 -> DESDE EL 01/04 AL 30/04/2026
C39: NOMBRES Y APELLIDOS: | E39: ='NOMINA DIRECTIVOS'!C12 -> KARELIS ADREINA ESPLUGUEZ SARMIENTO | J39: C.I.: | K39: ='NOMINA DIRECTIVOS'!D12 -> 16489561
C40: FECHA DE INGRESO: | E40: ='NOMINA DIRECTIVOS'!F12 -> 45219 | F40: CARGO: | G40: ='NOMINA DIRECTIVOS'!G12 -> VICEPRESIDENTE | J40: DPTO: | K40: ='NOMINA DIRECTIVOS'!H12 -> PRESIDENCIA
C41: TOTAL DEVENGADO:
C42: DIAS | D42: ='NOMINA EMPELADOS CDO'!I12 -> 30 | E42: SALARIO DIARIO: | G42: ='NOMINA DIRECTIVOS'!J12 -> 4871.192 | H42: BsS. | I42: =G42*D42 -> 146135.76 | J42: SALARIO MENSUAL: | L42: =G42*30 -> 146135.76
C43: H. EXTRAS DIURNAS | E43: Nº HORAS | F43: ='NOMINA EMPELADOS CDO'!P21 -> 0 | H43: BsS. | I43: ='NOMINA EMPELADOS CDO'!Q21 -> 0
C44: H EXTRAS NOCTURNAS | E44: Nº HORAS | F44: ='NOMINA EMPELADOS CDO'!R21 -> 0 | H44: BsS. | I44: ='NOMINA EMPELADOS CDO'!S21 -> 0
C45: SABADO | E45: Nº HORAS | F45: ='NOMINA EMPELADOS CDO'!M21 -> 0 | H45: BsS. | I45: ='NOMINA EMPELADOS CDO'!O21 -> 0
C46: RECARGO DOMINGO | E46: A Bs. | H46: BsS. | I46: ='NOMINA EMPELADOS CDO'!T21 -> 0
C47: FERIADO | E47: Nº HORAS | F47: ='NOMINA EMPELADOS CDO'!I21 -> 0 | H47: BsS. | I47: ='NOMINA EMPELADOS CDO'!J21 -> 0
C48: REEMBOLSO | E48: A Bs. | H48: BsS. | I48: ='NOMINA EMPELADOS CDO'!P12 -> 0
C49: TIEMPO DE VIAJE | F49: ='NOMINA EMPELADOS CDO'!R12 -> 0 | G49: HORAS | H49: BsS. | I49: ='NOMINA EMPELADOS CDO'!S12 -> 0
...

Sheet RESUMEN DE NOMINA
D2: COMERCIALIZADORA CASA DULCE ORIENTE, C.A RIF: J-50223534-5
C5: MES DE AGOSTO 2025
C6: DESDE EL 01/08 AL 31/08/2025 | AE6: TASA AL 30-07-2025
B7: NOMINA DE EMPLEADOS COMERCIALIZADORA CASA DULCE ORIENTE, C.A | AE7: 148.444
B9: COD | C9: NOMBRE Y APELLIDOS | D9: CEDULA | E9: RIF | F9: FECHA DE INGRESO | G9: CARGO | H9: DEPARTAMENTO | I9: DIAS TRABAJ. | J9: SALARIO | K9: SALARIO MENSUAL | L9: RETROACTIVO 15-06-2018 | M9: TOTAL SALARIO MENSUAL | N9: BONO COMPLEMENTARIO | O9: REEMB. | P9: RETROACTIVO POR AJUSTE DE SALARIO A PARTIR DEL 16-04-2019 | Q9: (HORAS) TIEMPO DE VIAJE | R9: PAGO TIEMPO DE VIAJE | S9: TOTAL DEVENGADO | T9: DEDUCCIONES | AB9: TOTAL PAGADO
M10: GANADO | T10: SEGURO SOCIAL | U10: PARO FORSOZO | V10: AHORRO HAB. | W10: I.S.L.R | X10: DESC. POR PRESTAMOS (1) | Y10: DESC. POR PRESTAMOS (2) | Z10: OTRAS | AA10: TOTAL DEDUCCIONES
B11: 1 | C11: DAIRILYS DEL CARMEN GUAREGUA CHAGUAN | D11: 16067033 | E11: V-16067033-5 | F11: 45001 | G11: ENCARGADA DE TIENDA | H11: ADMINISTRACION | I11: =ASISTENCIA!AA13 -> 30 | J11: 43.33 | K11: =J11*30 -> 1299.9 | L11: 0 | M11: =I11*J11 -> 1299.9 | N11: =(80*AE7)-M11 -> 10575.62 | O11: 0 | Q11: =ASISTENCIA!Z13 -> 0 | R11: =J11/8*Q11 -> 0 | S11: =M11+N11 -> 11875.52 | T11: =((J11/2)*30*12)/52*4%*4 -> 23.998154 | U11: =(J11*30*12)/52*0.5%*4 -> 5.9995385 | V11: =K11*1% -> 12.999 | W11: =+S11*1.82% -> 216.13446 | X11: 0 | Y11: 0 | Z11: 0 | AA11: =T11+U11+V11+W11 -> 259.13116 | AB11: =S11-AA11 -> 11616.389 | AC11: 17528.02
B12: =+B11+1 -> 2 | C12: EMILIO JOSÉ PINTO DOMIGUEZ | D12: 8326409 | E12: V-08326409-4 | F12: 45001 | G12: LOGISTICA | H12: OPERACIONES | I12: =ASISTENCIA!AA14 -> 30 | J12: =1300/30 -> 43.333333 | K12: =J12*30 -> 1300 | L12: 0 | M12: =I12*J12 -> 1300 | N12: =(120*AE7)-M12 -> 16513.28 | O12: =AF12 -> 0 | Q12: =ASISTENCIA!Z14 -> 0 | R12: =J12/8*Q12 -> 0 | S12: =M12+N12 -> 17813.28 | T12: =((J12/2)*30*12)/52*4%*4 -> 24 | U12: =(J12*30*12)/52*0.5%*4 -> 6 | V12: =K12*1% -> 13 | W12: =1.36%*S12 -> 242.26061 | X12: 0 | Y12: 0 | Z12: 0 | AA12: =T12+U12+V12+W12 -> 285.26061 | AB12: =S12-AA12 -> 17528.019 | AC12: 17528.02
B13: =+B12+1 -> 3 | C13: JESÚS RAFAEL ARAY CAGUANA | D13: 8234036 | E13: V-08234036-6 | F13: 45218 | G13: LOGISTICA | H13: OPERACIONES | I13: =ASISTENCIA!AA15 -> 30 | J13: =1300/30 -> 43.333333 | K13: =J13*30 -> 1300 | M13: =I13*J13 -> 1300 | N13: =(120*AE7)-M13 -> 16513.28 | S13: =M13+N13 -> 17813.28 | T13: =((J13/2)*30*12)/52*4%*4 -> 24 | U13: =(J13*30*12)/52*0.5%*4 -> 6 | V13: =K13*1% -> 13 | W13: =+S13*1.56% -> 277.88717 | AA13: =T13+U13+V13+W13 -> 320.88717 | AB13: =S13-AA13 -> 17492.393 | AC13: 17528.02
B14: =+B13+1 -> 4 | C14: THEISY DEL CARMEN NADALES LOPEZ | D14: 19316663 | E14: V-19316663-2 | F14: 45839 | G14: VENDEDORA | H14: ATENCION AL CLIENTE | I14: =ASISTENCIA!AA16 -> 30 | J14: =1300/30 -> 43.333333 | K14: =J14*30 -> 1300 | M14: =I14*J14 -> 1300 | N14: =(120*AE7)-M14 -> 16513.28 | S14: =M14+N14 -> 17813.28 | T14: =((J14/2)*30*12)/52*4%*4 -> 24 | U14: =(J14*30*12)/52*0.5%*4 -> 6 | V14: =K14*1% -> 13 | W14: =+S14*1.12% -> 199.50874 | AA14: =T14+U14+V14+W14 -> 242.50874 | AB14: =S14-AA14 -> 17570.771 | AC14: 17528.02
B15: =+B14+1 -> 5 | C15: MARIA VICTORIA GUAITA CANELON | D15: 31311552 | E15: V-31311552-2 | F15: 45839 | G15: CAJERA | H15: ATENCION AL CLIENTE | I15: =ASISTENCIA!AA17 -> 30 | J15: =1300/30 -> 43.333333 | K15: =J15*30 -> 1300 | L15: 1 | M15: =I15*J15 -> 1300 | N15: =+(120*AE7)-M15 -> 16513.28 | O15: =AF15 -> 0 | Q15: =ASISTENCIA!Z15 -> 0 | R15: =J15/8*Q15 -> 0 | S15: =M15+N15 -> 17813.28 | T15: =((J15/2)*30*12)/52*4%*4 -> 24 | U15: =(J15*30*12)/52*0.5%*4 -> 6 | V15: =K15*1% -> 13 | W15: =+S15*1.43% -> 254.7299 | X15: 0 | Y15: 0 | Z15: 0 | AA15: =T15+U15+V15+W15 -> 297.7299 | AB15: =S15-AA15 -> 17515.55 | AC15: 17528.02
J16: =SUM(J11:J15) -> 216.66333 | K16: =SUM(K11:K15) -> 6499.9 | L16: =SUM(L11:L12) -> 0 | M16: =SUM(M11:M12) -> 2599.9 | N16: =SUM(N11:N12) -> 27088.9 | O16: =SUM(O11:O12) -> 0 | P16: =SUM(P11:P12) -> 0 | Q16: =SUM(Q11:Q12) -> 0 | R16: =SUM(R11:R12) -> 0 | S16: =SUM(S11:S15) -> 83128.64 | T16: =SUM(T11:T15) -> 119.99815 | U16: =SUM(U11:U15) -> 29.999538 | V16: =SUM(V11:V15) -> 64.999 | W16: =SUM(W11:W12) -> 458.39507 | X16: =SUM(X11:X12) -> 0 | Y16: =SUM(Y11:Y12) -> 0 | Z16: =SUM(Z11:Z12) -> 0 | AA16: =SUM(AA11:AA15) -> 1405.5176 | AB16: =SUM(AB11:AB15) -> 81723.122 | AC16: =SUM(AC11:AC15) -> 87640.1
H19: EMPLEADOS | I19: HRS | J19: FERIADO | M19: HRS | N19: SABADO | O19: HRS | P19: S.D 24/06/2015 | Q19: HRS | R19: S.N | S19: RECARG. DOM. | T19: TOTAL HRS. | U19: TOTAL SOBRE-TIEMPO
H20: =C11 -> DAIRILYS DEL CARMEN GUAREGUA CHAGUAN | J20: =((J11)+(115%*J11))/8*I20 -> 0 | M20: 0 | N20: =((J11)+(115%*J11))/8*M20 -> 0 | O20: 0 | P20: =(J11/8*(90/100)+(J11/8))*O20 -> 0 | Q20: 0 | R20: =(J11/8*(115/100)+(J11/8))*Q20 -> 0 | S20: =(J20+N20+P20+R20)/7 -> 0 | T20: =I20+M20+O20+Q20 -> 0 | U20: =J20+N20+P20+R20+S20 -> 0
H21: =C12 -> EMILIO JOSÉ PINTO DOMIGUEZ | J21: =((J12)+(115%*J12))/8*I21 -> 0 | M21: 0 | N21: =((J12)+(115%*J12))/8*M21 -> 0 | O21: 0 | P21: =(J12/8*(90/100)+(J12/8))*O21 -> 0 | Q21: 0 | R21: =(J12/8*(115/100)+(J12/8))*Q21 -> 0 | S21: =(J21+N21+P21+R21)/7 -> 0 | T21: =I21+M21+O21+Q21 -> 0 | U21: =J21+N21+P21+R21+S21 -> 0
H22: =C13 -> JESÚS RAFAEL ARAY CAGUANA | J22: =((J13)+(115%*J13))/8*I22 -> 0 | M22: 0 | N22: =((J13)+(115%*J13))/8*M22 -> 0 | O22: 0 | P22: =(J13/8*(90/100)+(J13/8))*O22 -> 0 | Q22: 0 | R22: =(J13/8*(115/100)+(J13/8))*Q22 -> 0 | S22: =(J22+N22+P22+R22)/7 -> 0 | T22: =I22+M22+O22+Q22 -> 0 | U22: =J22+N22+P22+R22+S22 -> 0
H23: =C14 -> THEISY DEL CARMEN NADALES LOPEZ | J23: =((J14)+(115%*J14))/8*I23 -> 0 | M23: 0 | N23: =((J14)+(115%*J14))/8*M23 -> 0 | O23: 0 | P23: =(J14/8*(90/100)+(J14/8))*O23 -> 0 | Q23: 0 | R23: =(J14/8*(115/100)+(J14/8))*Q23 -> 0 | S23: =(J23+N23+P23+R23)/7 -> 0 | T23: =I23+M23+O23+Q23 -> 0 | U23: =J23+N23+P23+R23+S23 -> 0
H24: =C15 -> MARIA VICTORIA GUAITA CANELON | J24: =((J15)+(115%*J15))/8*I24 -> 0 | M24: 0 | N24: =((J15)+(115%*J15))/8*M24 -> 0 | O24: 0 | P24: =(J15/8*(90/100)+(J15/8))*O24 -> 0 | Q24: 0 | R24: =(J15/8*(115/100)+(J15/8))*Q24 -> 0 | S24: =(J24+N24+P24+R24)/7 -> 0 | T24: =I24+M24+O24+Q24 -> 0 | U24: =J24+N24+P24+R24+S24 -> 0
H25: =C16 -> 0 | J25: =((J16)+(115%*J16))/8*I25 -> 0 | M25: 0 | N25: =((J16)+(115%*J16))/8*M25 -> 0 | O25: 0 | P25: =(J16/8*(90/100)+(J16/8))*O25 -> 0 | Q25: 0 | R25: =(J16/8*(115/100)+(J16/8))*Q25 -> 0 | S25: =(J25+N25+P25+R25)/7 -> 0 | T25: =I25+M25+O25+Q25 -> 0 | U25: =J25+N25+P25+R25+S25 -> 0
I26: =SUM(I20:I21) -> 0 | J26: =SUM(J20:J21) -> 0 | M26: =SUM(M20:M21) -> 0 | N26: =SUM(N20:N21) -> 0 | O26: =SUM(O20:O21) -> 0 | P26: =SUM(P20:P21) -> 0 | Q26: =SUM(Q20:Q21) -> 0 | R26: =SUM(R20:R21) -> 0 | S26: =SUM(S20:S21) -> 0 | T26: =SUM(T20:T21) -> 0 | U26: =SUM(U20:U21) -> 0

Sheet ASISTENCIA
B7: ASISTENCIAS DE EMPLEADOS
B8: ='NOMINA EMPELADOS CDO'!C5 -> MES DE ABRIL 2026
B9: ='NOMINA EMPELADOS CDO'!C6 -> DESDE EL 01/04 AL 30/04/2026
B10: COD | C10: TRABAJADOR | D10: 21 | G10: 22 | J10: =G10+1 -> 23 | M10: =J10+1 -> 24 | P10: =M10+1 -> 25 | S10: =P10+1 -> 26 | V10: =S10+1 -> 27 | Z10: TOTAL A PAGAR TIEMPO DE VIAJE | AA10: TOTAL A PAGAR DIAS | AB10: DESCUENTO DE HORAS | AC10: OBSERVACIÓN
D11: D | E11: S | G11: L | J11: M | K11: S | M11: M | P11: J | S11: V | T11: S | V11: S
B13: 1 | C13: ='NOMINA EMPELADOS CDO'!C11 -> DAIRILYS DEL CARMEN GUAREGUA CHAGUAN | G13: X | H13: X | J13: X | K13: X | M13: X | N13: X | P13: X | Q13: X | S13: X | T13: X | Z13: 0 | AA13: 30 | AB13: 0 | AC13: NINGUNA
B14: 2 | C14: ='NOMINA EMPELADOS CDO'!C12 -> EMILIO JOSÉ PINTO DOMIGUEZ | G14: X | H14: X | J14: X | K14: X | M14: X | N14: X | P14: X | Q14: X | S14: X | T14: X | Z14: 0 | AA14: 30 | AB14: 0 | AC14: NINGUNA
B15: 3 | C15: ='NOMINA EMPELADOS CDO'!C13 -> JESÚS RAFAEL ARAY CAGUANA | G15: X | H15: X | J15: X | K15: X | M15: X | N15: X | P15: X | Q15: X | S15: X | T15: X | Z15: 0 | AA15: 30 | AB15: 0 | AC15: NINGUNA
B16: 4 | C16: ='NOMINA EMPELADOS CDO'!C14 -> THEISY DEL CARMEN NADALES LOPEZ | G16: X | H16: X | J16: X | K16: X | M16: X | N16: X | P16: X | Q16: X | S16: X | T16: X | Z16: 0 | AA16: 30 | AB16: 0 | AC16: NINGUNA
B17: 5 | C17: ='NOMINA EMPELADOS CDO'!C15 -> MARIA VICTORIA GUAITA CANELON | G17: X | H17: X | J17: X | K17: X | M17: X | N17: X | P17: X | Q17: X | S17: X | T17: X | Z17: 0 | AA17: 30 | AB17: 0 | AC17: NINGUNA
C19: DIA DEL TRABAJADOR
C21: PERMISO PERSONALES
C23: REPOSO NATURAL
C27: =18000*16% -> 2880
C28: =18000+2880 -> 20880
