Workbook

Sheet LEO SOTO
B3: CUADRO DE DIAS LABORADOS | C3: DESDE | D3: HASTA
B4: PRERIODO LABORAL
B5: NOMBRE DE EMPLEADO | C5: LEO
B6: RANGO HORARIO | C6: 0.33333333 | D6: HORAS | H6: DETALLE DE QUINCENA
E8: FECHA: | F8: =TODAY() -> 44716 | H8: NOMBRE: | I8: LEO | J8: FECHA: | K8: =TODAY() -> 44716
B9: FECHA | C9: ENTRADA | D9: SALIDA | E9: TOTAL | F9: EXTRAS | H9: CONCEPTO | I9: VALOR | J9: CANTIDAD | K9: SUB TOTAL
B10: 44651 | C10: 0.29166667 | D10: 0.72222222 | E10: =D10-C10 -> 0.43055556 | F10: =E10-$C$6 -> 0.097222222 | H10: HORA SIMPLE | I10: 5000 | J10: 11 | K10: =Tabla27[[#This Row],[VALOR]]*Tabla27[[#This Row],[CANTIDAD]] -> 55000
B11: 44652 | C11: 0.29166667 | D11: 0.71875 | E11: 0.80208333 | F11: 0.46875 | H11: HORA EXTRA | I11: 7500 | J11: 30 | K11: =Tabla27[[#This Row],[VALOR]]*Tabla27[[#This Row],[CANTIDAD]] -> 225000
B12: 44653 | C12: 0.29166667 | D12: 0.66666667 | E12: =D12-C12 -> 0.375 | F12: 0.041666667 | H12: HORA RECIBO | I12: 4313.43 | J12: 88 | K12: 323897
B13: 44654 | C13: 0.29166667 | D13: 0.58541667 | E13: =D13-C13 -> 0.29375 | F13: 0.29375 | H13: VIATICOS | I13: 6000 | J13: 11 | K13: =Tabla27[[#This Row],[VALOR]]*Tabla27[[#This Row],[CANTIDAD]] -> 66000
B14: 44655 | E14: =D14-C14 -> 0 | F14: 0 | H14: CATEGORIA | I14: 50000 | J14: 1 | K14: =Tabla27[[#This Row],[VALOR]]*Tabla27[[#This Row],[CANTIDAD]] -> 50000
B15: 44656 | C15: 0.29166667 | D15: 0.70416667 | E15: =D15-C15 -> 0.4125 | F15: =E15-$C$6 -> 0.079166667 | H15: PREMIO | I15: 90000 | J15: 1 | K15: =Tabla27[[#This Row],[VALOR]]*Tabla27[[#This Row],[CANTIDAD]] -> 90000
B16: 44657 | C16: 0.29166667 | D16: 0.70625 | E16: =D16-C16 -> 0.41458333 | F16: =E16-$C$6 -> 0.08125 | K16: =Tabla27[[#This Row],[VALOR]]*Tabla27[[#This Row],[CANTIDAD]] -> 0
B17: 44658 | C17: 0.29166667 | D17: 0.74791667 | E17: =D17-C17 -> 0.45625 | F17: =E17-$C$6 -> 0.12291667 | H17: Total | K17: =SUBTOTAL(109,Tabla27[SUB TOTAL]) -> 809897
B18: 44659 | C18: 0.29166667 | D18: 0.70972222 | E18: =D18-C18 -> 0.41805556 | F18: =E18-$C$6 -> 0.084722222 | H18: DESCUENTOS
B19: 44660 | C19: 0.29166667 | D19: 0.74236111 | E19: =D19-C19 -> 0.45069444 | F19: =E19-$C$6 -> 0.11736111 | H19: FECHA | I19: CONCEPTO | J19: CANTIDAD | K19: TOTAL
B20: 44661 | E20: =D20-C20 -> 0 | F20: 0 | H20: 44670 | I20: DP Sueldo | J20: =K12 -> 323897 | K20: =Tabla27[[#Totals],[SUB TOTAL]]-J20 -> 486000
B21: 44662 | E21: =D21-C21 -> 0 | F21: 0 | I21: PRESTAMO | J21: 100000 | K21: =K20-J21 -> 386000
B22: 44663 | C22: 0.29166667 | D22: 0.71388889 | E22: =D22-C22 -> 0.42222222 | F22: =E22-$C$6 -> 0.088888889 | I22: ADELANTO | J22: 200000 | K22: =K21-J22 -> 186000
B23: 44664 | C23: 0.29166667 | D23: 0.77013889 | E23: =D23-C23 -> 0.47847222 | F23: =E23-$C$6 -> 0.14513889 | J23: 0 | K23: =K22-J23 -> 186000
B24: 44665 | C24: 0.29305556 | D24: 0.70833333 | E24: =D24-C24 -> 0.41527778 | F24: =E24-$C$6 -> 0.081944444 | K24: =K23-J24 -> 186000
E25: =D25-C25 -> 0 | F25: 0 | H25: FIRMA CONFORME ___________________________
B26: Total | C26: =SUBTOTAL(102,Tabla16[ENTRADA]) -> 12 | E26: =SUBTOTAL(109,E10:E25) -> 5.3694444 | F26: =SUBTOTAL(109,F10:F25) -> 1.7027778
D27: HORAS RECIBO | E27: =Tabla16[[#Totals],[TOTAL]]-Tabla16[[#Totals],[EXTRAS]] -> 3.6666667 | F27: HORAS
D28: HORAS EXTRAS | E28: =Tabla16[[#Totals],[EXTRAS]] -> 1.7027778 | F28: HORAS
D29: DIAS HABILES | E29: 12 | F29: DIAS
D30: SABADOS | E30: 2 | F30: DIAS
D31: HORAS SIMPLES | E31: =E6*11 -> 0 | F31: HORAS
D32: HORAS EXTRAS A PAGAR: | F32: HORAS
B33: No: | D33: 120 | J33: Nom. | L33: LEO SOTO
B34: 06:38 17:20 | C34: 07:00 17:15 | E34: 06:31 14:03 | G34: 06:16 16:54 | H34: 06:22 16:57 | I34: 06:50 17:57 | J34: 06:49 17:02 | K34: 06:59 17:49 | N34: 06:48 17:08 | O34: 06:47 18:29 | P34: 0.29305556

Sheet GABRIEL
A2: CUADRO DE DIAS LABORADOS | B2: DESDE | C2: HASTA
A3: PRERIODO LABORAL
A4: NOMBRE DE EMPLEADO | B4: GABRIEL
A5: RANGO HORARIO | B5: 0.33333333 | C5: HORAS | G5: DETALLE DE QUINCENA
D8: FECHA: | E8: =TODAY() -> 44716 | G8: NOMBRE: | H8: GABRIEL | I8: FECHA: | J8: =TODAY() -> 44716
A9: FECHA | B9: ENTRADA | C9: SALIDA | D9: TOTAL | E9: EXTRAS | G9: CONCEPTO | H9: VALOR | I9: CANTIDAD | J9: SUB TOTAL
A10: 44651 | B10: 0.29166667 | C10: 0.72569444 | D10: =C10-B10 -> 0.43402778 | E10: =D10-$B$5 -> 0.10069444 | G10: HORA SIMPLE | H10: 5000 | I10: 11 | J10: =Tabla272[[#This Row],[VALOR]]*Tabla272[[#This Row],[CANTIDAD]] -> 55000
A11: 44652 | B11: 0.31041667 | C11: 0.70833333 | D11: 0.77291667 | E11: 0.43958333 | G11: HORA EXTRA | H11: 7500 | I11: 33 | J11: =Tabla272[[#This Row],[VALOR]]*Tabla272[[#This Row],[CANTIDAD]] -> 247500
A12: 44653 | B12: 0.29166667 | C12: 0.66666667 | D12: =C12-B12 -> 0.375 | E12: 0.041666667 | G12: HORA DE RECIBO | H12: 4313.43 | I12: 88 | J12: 308619
A13: 44654 | B13: 0.29166667 | C13: 0.58541667 | D13: =C13-B13 -> 0.29375 | E13: 0.29375 | G13: VIATICOS | H13: 6000 | I13: 12 | J13: =Tabla272[[#This Row],[VALOR]]*Tabla272[[#This Row],[CANTIDAD]] -> 72000
A14: 44655 | D14: =C14-B14 -> 0 | E14: 0 | G14: CATEGORIA | H14: 35000 | I14: 1 | J14: =Tabla272[[#This Row],[VALOR]]*Tabla272[[#This Row],[CANTIDAD]] -> 35000
A15: 44656 | B15: 0.29166667 | C15: 0.71875 | D15: =C15-B15 -> 0.42708333 | E15: =D15-$B$5 -> 0.09375 | G15: PREMIO | H15: 90000 | I15: 1 | J15: =Tabla272[[#This Row],[VALOR]]*Tabla272[[#This Row],[CANTIDAD]] -> 90000
A16: 44657 | B16: 0.29166667 | C16: 0.70972222 | D16: =C16-B16 -> 0.41805556 | E16: =D16-$B$5 -> 0.084722222 | J16: =Tabla272[[#This Row],[VALOR]]*Tabla272[[#This Row],[CANTIDAD]] -> 0
A17: 44658 | B17: 0.29166667 | C17: 0.75347222 | D17: =C17-B17 -> 0.46180556 | E17: =D17-$B$5 -> 0.12847222 | G17: Total | J17: =SUBTOTAL(109,Tabla272[SUB TOTAL]) -> 808119
A18: 44659 | B18: 0.29166667 | C18: 0.71805556 | D18: =C18-B18 -> 0.42638889 | E18: =D18-$B$5 -> 0.093055556 | G18: DESCUENTOS
A19: 44660 | B19: 0.29166667 | C19: 0.72013889 | D19: =C19-B19 -> 0.42847222 | E19: =D19-$B$5 -> 0.095138889 | G19: FECHA | H19: CONCEPTO | I19: CANTIDAD | J19: TOTAL
A20: 44661 | B20: 0.29791667 | C20: 0.47847222 | D20: =C20-B20 -> 0.18055556 | E20: 0.18055556 | G20: 44670 | H20: DEPOSITO RECIBO | I20: =J12 -> 308619 | J20: =Tabla272[[#Totals],[SUB TOTAL]]-I20 -> 499500
A21: 44662 | D21: =C21-B21 -> 0 | E21: 0 | H21: ADELANTO | I21: 410375 | J21: =J20-I21 -> 89125
A22: 44663 | B22: 0.29166667 | C22: 0.71458333 | D22: =C22-B22 -> 0.42291667 | E22: =D22-$B$5 -> 0.089583333 | J22: =J21-I22 -> 89125
A23: 44664 | B23: 0.29166667 | C23: 0.75555556 | D23: =C23-B23 -> 0.46388889 | E23: =D23-$B$5 -> 0.13055556 | J23: =J22-I23 -> 89125
A24: 44665 | B24: 0.3 | C24: 0.70833333 | D24: =C24-B24 -> 0.40833333 | E24: =D24-$B$5 -> 0.075
D25: =C25-B25 -> 0 | E25: 0 | G25: FIRMA CONFORME ___________________________
A26: Total | D26: =SUBTOTAL(109,D10:D25) -> 5.5131944 | E26: =SUBTOTAL(109,E10:E25) -> 1.8465278
C27: HORAS EXTRAS | D27: =Tabla165[[#Totals],[TOTAL]]-Tabla165[[#Totals],[EXTRAS]] -> 3.6666667 | E27: HORAS
C28: DIAS HABILES | D28: 12 | E28: DIAS
C29: SABADOS | D29: 0 | E29: DIAS
C30: HORAS SIMPLES | E30: HORAS
C31: HORAS EXTRAS A PAGAR: | D31: 0.041666667 | E31: HORAS
C32: FALTAS | D32: 0 | E32: DIAS
A33: No: | C33: 17 | I33: Nom. | K33: GABRIEL
A34: 06:24 17:25 | B34: 07:27 17:00 | D34: 06:31 14:03 | F34: 06:14 17:15 | G34: 06:16 06:17 17:02 | H34: 06:10 18:05 | I34: 06:16 17:14 | J34: 06:26 17:17 | K34: 07:09 11:29 | M34: 06:11 17:09 | N34: 06:33 18:08 | O34: 0.3

Sheet DANIEL
B2: CUADRO DE DIAS LABORADOS | C2: DESDE | D2: HASTA
B3: PRERIODO LABORAL
B4: NOMBRE DE EMPLEADO | C4: DANIEL
B5: RANGO HORARIO | C5: 0.375 | D5: HORAS | H5: DETALLE DE QUINCENA
E7: FECHA: | F7: =TODAY() -> 44716 | H7: NOMBRE: | I7: DANIEL | J7: FECHA: | K7: =TODAY() -> 44716
B8: FECHA | C8: ENTRADA | D8: SALIDA | E8: TOTAL | F8: EXTRAS | H8: CONCEPTO | I8: VALOR | J8: CANTIDAD | K8: SUB TOTAL
B9: 44651 | C9: 0.29166667 | D9: 0.72291667 | E9: =D9-C9 -> 0.43125 | F9: =E9-$C$5 -> 0.05625 | H9: HORA SIMPLE | I9: 5000 | J9: 99 | K9: =Tabla23141114161820[[#This Row],[VALOR]]*Tabla23141114161820[[#This Row],[CANTIDAD]] -> 495000
B10: 44652 | C10: 0.23541667 | D10: 0.70833333 | E10: 0.84791667 | F10: 0.47291667 | H10: HORA EXTRA | I10: 7500 | J10: 32 | K10: =Tabla23141114161820[[#This Row],[VALOR]]*Tabla23141114161820[[#This Row],[CANTIDAD]] -> 240000
B11: 44653 | C11: 0.29166667 | D11: 0.66666667 | E11: =D11-C11 -> 0.375 | F11: =E11-$C$5 -> 0 | H11: VIATICOS | I11: 6000 | J11: 11 | K11: =Tabla23141114161820[[#This Row],[VALOR]]*Tabla23141114161820[[#This Row],[CANTIDAD]] -> 66000
B12: 44654 | C12: 0.29166667 | D12: 0.58125 | E12: =D12-C12 -> 0.28958333 | F12: 0.28958333 | H12: PREMIO | I12: 90000 | J12: 1 | K12: =Tabla23141114161820[[#This Row],[VALOR]]*Tabla23141114161820[[#This Row],[CANTIDAD]] -> 90000
B13: 44655 | E13: =D13-C13 -> 0 | F13: 0 | H13: CATEGORIA | I13: 35000 | J13: 1 | K13: =Tabla23141114161820[[#This Row],[VALOR]]*Tabla23141114161820[[#This Row],[CANTIDAD]] -> 35000
B14: 44656 | C14: 0.29166667 | D14: 0.70416667 | E14: =D14-C14 -> 0.4125 | F14: =E14-$C$5 -> 0.0375 | K14: =Tabla23141114161820[[#This Row],[VALOR]]*Tabla23141114161820[[#This Row],[CANTIDAD]] -> 0
B15: 44657 | C15: 0.29166667 | D15: 0.75625 | E15: =D15-C15 -> 0.46458333 | F15: =E15-$C$5 -> 0.089583333 | H15: Total | K15: =SUBTOTAL(109,Tabla23141114161820[SUB TOTAL]) -> 926000
B16: 44658 | C16: 0.29166667 | D16: 0.75347222 | E16: =D16-C16 -> 0.46180556 | F16: =E16-$C$5 -> 0.086805556 | H16: DESCUENTOS
B17: 44659 | C17: 0.29166667 | D17: 0.70763889 | E17: =D17-C17 -> 0.41597222 | F17: =E17-$C$5 -> 0.040972222 | H17: FECHA | I17: CONCEPTO | J17: CANTIDAD | K17: TOTAL
B18: 44660 | C18: 0.29166667 | D18: 0.74236111 | E18: =D18-C18 -> 0.45069444 | F18: =E18-$C$5 -> 0.075694444 | H18: 44670 | I18: ADELANTO | J18: 60000 | K18: =Tabla23141114161820[[#Totals],[SUB TOTAL]]-Tabla332101315171922[[#This Row],[CANTIDAD]] -> 866000
B19: 44661 | E19: =D19-C19 -> 0 | F19: 0 | K19: =K18-Tabla332101315171922[[#This Row],[CANTIDAD]] -> 866000
B20: 44662 | E20: =D20-C20 -> 0 | F20: 0 | K20: =K19-Tabla332101315171922[[#This Row],[CANTIDAD]] -> 866000
B21: 44663 | C21: 0.29166667 | D21: 0.71597222 | E21: =D21-C21 -> 0.42430556 | F21: =E21-$C$5 -> 0.049305556 | H21: FIRMA CONFORME ___________________________
B22: 44664 | C22: 0.29166667 | D22: 0.76597222 | E22: =D22-C22 -> 0.47430556 | F22: =E22-$C$5 -> 0.099305556
B23: 44665 | C23: 0.29166667 | D23: 0.70833333 | E23: =D23-C23 -> 0.41666667 | F23: =E23-$C$5 -> 0.041666667
E24: =D24-C24 -> 0 | F24: 0
B25: Total | C25: =SUBTOTAL(102,Tabla13040[ENTRADA]) -> 12 | E25: =SUBTOTAL(109,E9:E24) -> 5.4645833 | F25: =SUBTOTAL(109,Tabla13040[EXTRAS]) -> 1.3395833
D26: HORAS SIMPLES | E26: =Tabla13040[[#Totals],[TOTAL]]-Tabla13040[[#Totals],[EXTRAS]] -> 4.125 | F26: HORAS
D27: HORAS EXTRAS | E27: 0 | F27: HORAS
D28: DIAS HABILES | E28: 11 | F28: DIAS
D29: SABADOS | E29: 0 | F29: DIAS
A30: No: | C30: 13 | I30: Nom. | K30: DANIEL
A31: 06:38 17:21 | B31: 05:39 17:00 17:04 | D31: 06:31 13:57 | F31: 06:16 16:54 | G31: 06:44 18:09 | H31: 0.75347222 | I31: 0.70763889 | J31: 06:59 06:59 17:49 | M31: 06:47 17:11 | N31: 06:47 18:23 | O31: 0.29305556

Sheet ISAIAS
B2: CUADRO DE DIAS LABORADOS | C2: DESDE | D2: HASTA
B3: PRERIODO LABORAL
B4: NOMBRE DE EMPLEADO | H4: DETALLE DE QUINCENA
B5: RANGO HORARIO | C5: 0.375 | D5: HORAS
E6: FECHA: | F6: =TODAY() -> 44716 | H6: NOMBRE: | I6: ISAIAS | J6: FECHA: | K6: =TODAY() -> 44716
B7: FECHA | C7: ENTRADA | D7: SALIDA | E7: TOTAL | F7: EXTRAS | H7: CONCEPTO | I7: VALOR | J7: CANTIDAD | K7: SUB TOTAL
B8: 44651 | C8: 0.29166667 | D8: 0.725 | E8: =D8-C8 -> 0.43333333 | F8: =Tabla13034[[#This Row],[TOTAL]]-$C$5 -> 0.058333333 | H8: HORAS | I8: 5000 | J8: 99 | K8: =Tabla2314[[#This Row],[VALOR]]*Tabla2314[[#This Row],[CANTIDAD]] -> 495000
B9: 44652 | C9: 0.29166667 | D9: 0.70833333 | E9: 0.79166667 | F9: 0.41666667 | H9: HORA EXTRA | I9: 7500 | J9: 32 | K9: =Tabla2314[[#This Row],[VALOR]]*Tabla2314[[#This Row],[CANTIDAD]] -> 240000
B10: 44653 | C10: 0.29166667 | D10: 0.66666667 | E10: =D10-C10 -> 0.375 | F10: =Tabla13034[[#This Row],[TOTAL]]-$C$5 -> 0 | H10: VIATICOS | I10: 6000 | J10: 12 | K10: =Tabla2314[[#This Row],[VALOR]]*Tabla2314[[#This Row],[CANTIDAD]] -> 72000
B11: 44654 | C11: 0.29166667 | D11: 0.58333333 | E11: 0.25 | F11: 0.25 | H11: PREMIO | I11: 90000 | J11: 1 | K11: =Tabla2314[[#This Row],[VALOR]]*Tabla2314[[#This Row],[CANTIDAD]] -> 90000
B12: 44655 | E12: =D12-C12 -> 0 | F12: 0 | H12: CATEGORIA | I12: 35000 | J12: 1 | K12: =Tabla2314[[#This Row],[VALOR]]*Tabla2314[[#This Row],[CANTIDAD]] -> 35000
B13: 44656 | C13: 0.29166667 | D13: 0.71875 | E13: =D13-C13 -> 0.42708333 | F13: =Tabla13034[[#This Row],[TOTAL]]-$C$5 -> 0.052083333 | K13: =Tabla2314[[#This Row],[VALOR]]*Tabla2314[[#This Row],[CANTIDAD]] -> 0
B14: 44657 | C14: 0.29166667 | D14: 0.71041667 | E14: =D14-C14 -> 0.41875 | F14: =Tabla13034[[#This Row],[TOTAL]]-$C$5 -> 0.04375 | H14: Total | K14: =SUBTOTAL(109,Tabla2314[SUB TOTAL]) -> 932000
B15: 44658 | C15: 0.29166667 | D15: 0.70486111 | E15: =D15-C15 -> 0.41319444 | F15: =Tabla13034[[#This Row],[TOTAL]]-$C$5 -> 0.038194444 | H15: DESCUENTOS
B16: 44659 | C16: 0.29166667 | D16: 0.71736111 | E16: =D16-C16 -> 0.42569444 | F16: =Tabla13034[[#This Row],[TOTAL]]-$C$5 -> 0.050694444 | H16: FECHA | I16: CONCEPTO | J16: CANTIDAD | K16: TOTAL
B17: 44660 | C17: 0.29166667 | D17: 0.71944444 | E17: =D17-C17 -> 0.42777778 | F17: =Tabla13034[[#This Row],[TOTAL]]-$C$5 -> 0.052777778 | H17: 44670 | I17: ADELANTO | J17: 200000 | K17: =Tabla2314[[#Totals],[SUB TOTAL]]-Tabla33210[[#This Row],[CANTIDAD]] -> 732000
B18: 44661 | C18: 0.29166667 | D18: 0.47777778 | E18: =D18-C18 -> 0.18611111 | F18: 0.18611111 | K18: =K17-Tabla33210[[#This Row],[CANTIDAD]] -> 732000
B19: 44662 | E19: =D19-C19 -> 0 | F19: 0 | K19: =K18-Tabla33210[[#This Row],[CANTIDAD]] -> 732000
B20: 44663 | C20: 0.29166667 | D20: 0.71527778 | E20: =D20-C20 -> 0.42361111 | F20: =Tabla13034[[#This Row],[TOTAL]]-$C$5 -> 0.048611111 | H20: FIRMA CONFORME ___________________________
B21: 44664 | C21: 0.29166667 | D21: 0.75555556 | E21: =D21-C21 -> 0.46388889 | F21: =Tabla13034[[#This Row],[TOTAL]]-$C$5 -> 0.088888889
B22: 44665 | C22: 0.29166667 | D22: 0.70833333 | E22: =D22-C22 -> 0.41666667 | F22: =Tabla13034[[#This Row],[TOTAL]]-$C$5 -> 0.041666667
E23: =D23-C23 -> 0 | F23: 0
B24: Total | C24: =SUBTOTAL(102,Tabla13034[ENTRADA]) -> 13 | E24: =SUBTOTAL(109,E8:E23) -> 5.4527778 | F24: =SUBTOTAL(109,Tabla13034[EXTRAS]) -> 1.3277778
D25: HORAS SIMPLES | E25: =Tabla13034[[#Totals],[TOTAL]]-Tabla13034[[#Totals],[EXTRAS]] -> 4.125 | F25: HORAS
D26: HORAS EXTRAS | E26: =Tabla13034[[#Totals],[EXTRAS]] -> 1.3277778 | F26: HORAS
D27: DIAS HABILES | E27: 11 | F27: DIAS
D28: SABADOS | E28: 2 | F28: DIAS
A29: No: | C29: 22 | I29: Nom. | K29: ISAIAS
A30: 05:46 17:24 | B30: 06:58 17:00 | D30: 0.58541667 | F30: 06:14 17:15 | G30: 06:16 17:03 | H30: 06:11 16:55 | I30: 06:16 06:47 17:13 | J30: 06:26 17:16 | K30: 06:48 11:28 | M30: 06:11 06:48 17:10 | N30: 06:33 18:08 | O30: 0.3

Sheet WALTER
B2: CUADRO DE DIAS LABORADOS | C2: DESDE | D2: HASTA
B3: PRERIODO LABORAL
B4: NOMBRE DE EMPLEADO | H4: DETALLE DE QUINCENA
B5: RANGO HORARIO | C5: 0.375 | D5: HORAS
E6: FECHA: | F6: =TODAY() -> 44716 | H6: NOMBRE: | I6: WALTER | J6: FECHA: | K6: =TODAY() -> 44716
B7: FECHA | C7: ENTRADA | D7: SALIDA | E7: TOTAL | F7: EXTRAS | H7: CONCEPTO | I7: VALOR | J7: CANTIDAD | K7: SUB TOTAL
B8: 44651 | C8: 0.29166667 | D8: 0.72361111 | E8: =D8-C8 -> 0.43194444 | F8: =E8-$C$5 -> 0.056944444 | H8: HORA SIMPLE | I8: 5000 | J8: 99 | K8: =Tabla23141114[[#This Row],[VALOR]]*Tabla23141114[[#This Row],[CANTIDAD]] -> 495000
B9: 44652 | C9: 0.23541667 | D9: 0.71875 | E9: 0.85833333 | F9: 0.48333333 | H9: HORA EXTRA | I9: 7500 | J9: 30 | K9: =Tabla23141114[[#This Row],[VALOR]]*Tabla23141114[[#This Row],[CANTIDAD]] -> 225000
B10: 44653 | C10: 0.29166667 | D10: 0.66666667 | E10: =D10-C10 -> 0.375 | F10: =E10-$C$5 -> 0 | H10: VIATICOS | I10: 6000 | J10: 11 | K10: =Tabla23141114[[#This Row],[VALOR]]*Tabla23141114[[#This Row],[CANTIDAD]] -> 66000
B11: 44654 | E11: =D11-C11 -> 0 | F11: 0 | H11: PREMIO | I11: 70000 | J11: 1 | K11: =Tabla23141114[[#This Row],[VALOR]]*Tabla23141114[[#This Row],[CANTIDAD]] -> 70000
B12: 44655 | E12: =D12-C12 -> 0 | F12: 0 | H12: CATEGORIA | I12: 35000 | J12: 1 | K12: =Tabla23141114[[#This Row],[VALOR]]*Tabla23141114[[#This Row],[CANTIDAD]] -> 35000
B13: 44656 | C13: 0.29166667 | D13: 0.66111111 | E13: =D13-C13 -> 0.36944444 | F13: =E13-$C$5 -> -0.0055555556 | K13: =Tabla23141114[[#This Row],[VALOR]]*Tabla23141114[[#This Row],[CANTIDAD]] -> 0
B14: 44657 | C14: 0.29166667 | D14: 0.75555556 | E14: =D14-C14 -> 0.46388889 | F14: =E14-$C$5 -> 0.088888889 | H14: Total | K14: =SUBTOTAL(109,Tabla23141114[SUB TOTAL]) -> 891000
B15: 44658 | C15: 0.29166667 | D15: 0.79652778 | E15: =D15-C15 -> 0.50486111 | F15: =E15-$C$5 -> 0.12986111 | H15: DESCUENTOS
B16: 44659 | C16: 0.29166667 | D16: 0.70833333 | E16: =D16-C16 -> 0.41666667 | F16: =E16-$C$5 -> 0.041666667 | H16: FECHA | I16: CONCEPTO | J16: CANTIDAD | K16: TOTAL
B17: 44660 | C17: 0.29166667 | D17: 0.74236111 | E17: =D17-C17 -> 0.45069444 | F17: =E17-$C$5 -> 0.075694444 | H17: 44670 | I17: ADELANTO | J17: 150000 | K17: =Tabla23141114[[#Totals],[SUB TOTAL]]-Tabla332101315[[#This Row],[CANTIDAD]] -> 741000
B18: 44661 | C18: 0.30069444 | D18: 0.47916667 | E18: =D18-C18 -> 0.17847222 | F18: 0.17847222 | K18: =K17-Tabla332101315[[#This Row],[CANTIDAD]] -> 741000
B19: 44662 | E19: =D19-C19 -> 0 | F19: 0 | K19: =K18-Tabla332101315[[#This Row],[CANTIDAD]] -> 741000
B20: 44663 | C20: 0.29166667 | D20: 0.71597222 | E20: =D20-C20 -> 0.42430556 | F20: =E20-$C$5 -> 0.049305556 | H20: FIRMA CONFORME ___________________________
B21: 44664 | C21: 0.29166667 | D21: 0.77013889 | E21: =D21-C21 -> 0.47847222 | F21: =E21-$C$5 -> 0.10347222
B22: 44665 | C22: 0.29166667 | D22: 0.70833333 | E22: =D22-C22 -> 0.41666667 | F22: =E22-$C$5 -> 0.041666667
E23: =D23-C23 -> 0 | F23: 0
B24: Total | E24: =SUBTOTAL(109,E8:E23) -> 5.36875 | F24: =SUBTOTAL(109,Tabla13037[EXTRAS]) -> 1.24375
D25: HORAS SIMPLES | E25: =Tabla13037[[#Totals],[TOTAL]]-Tabla13037[[#Totals],[EXTRAS]] -> 4.125 | F25: HORAS
D26: HORAS EXTRAS | E26: =Tabla13037[[#Totals],[EXTRAS]] -> 1.24375 | F26: HORAS
D27: DIAS HABILES | E27: 11 | F27: DIAS
A28: No: | C28: 25 | I28: Nom. | K28: WALTER
A29: 06:48 17:22 | B29: 05:39 17:15 | F29: 06:25 15:52 | G29: 06:20 18:08 | H29: 06:44 19:07 | I29: 0.70833333 | J29: 06:54 17:49 | K29: 0.30069444 | M29: 0.71597222 | N29: 06:47 18:29 | O29: 0.29305556

Sheet MIGUEL
B2: CUADRO DE DIAS LABORADOS | C2: DESDE | D2: HASTA
B3: PRERIODO LABORAL
B4: NOMBRE DE EMPLEADO | C4: MIGUEL | H4: DETALLE
B5: RANGO HORARIO | C5: 0.375 | D5: HORAS
E6: FECHA: | F6: =TODAY() -> 44716 | H6: NOMBRE: | I6: MIGUEL | J6: FECHA: | K6: =TODAY() -> 44716
B7: FECHA | C7: ENTRADA | D7: SALIDA | E7: TOTAL | F7: EXTRAS | H7: CONCEPTO | I7: VALOR | J7: CANTIDAD | K7: SUB TOTAL
B8: 44651 | C8: 0.29166667 | D8: 0.70625 | E8: =D8-C8 -> 0.41458333 | F8: =E8-$C$5 -> 0.039583333 | H8: HORA SIMPLE | I8: 4500 | J8: 99 | K8: =Tabla231[[#This Row],[VALOR]]*Tabla231[[#This Row],[CANTIDAD]] -> 445500
B9: 44652 | C9: 0.29166667 | D9: 0.63055556 | E9: 0.71388889 | F9: 0.33888889 | H9: HORA EXTRA | I9: 6750 | J9: 17 | K9: =Tabla231[[#This Row],[VALOR]]*Tabla231[[#This Row],[CANTIDAD]] -> 114750
B10: 44653 | C10: 0.29166667 | D10: 0.66666667 | E10: =D10-C10 -> 0.375 | F10: =E10-$C$5 -> 0 | H10: VIATICOS | I10: 6000 | J10: 10 | K10: =Tabla231[[#This Row],[VALOR]]*Tabla231[[#This Row],[CANTIDAD]] -> 60000
B11: 44654 | E11: =D11-C11 -> 0 | F11: 0 | H11: PREMIO | I11: 70000 | J11: 1 | K11: =Tabla231[[#This Row],[VALOR]]*Tabla231[[#This Row],[CANTIDAD]] -> 70000
B12: 44655 | E12: =D12-C12 -> 0 | F12: 0 | K12: =Tabla231[[#This Row],[VALOR]]*Tabla231[[#This Row],[CANTIDAD]] -> 0
B13: 44656 | C13: 0.29166667 | D13: 0.70416667 | E13: =D13-C13 -> 0.4125 | F13: =E13-$C$5 -> 0.0375 | H13: Total | K13: =SUBTOTAL(109,Tabla231[SUB TOTAL]) -> 690250
B14: 44657 | C14: 0.29166667 | D14: 0.70486111 | E14: =D14-C14 -> 0.41319444 | F14: =E14-$C$5 -> 0.038194444 | H14: DESCUENTOS
B15: 44658 | C15: 0.29166667 | D15: 0.70486111 | E15: =D15-C15 -> 0.41319444 | F15: =E15-$C$5 -> 0.038194444 | H15: FECHA | I15: CONCEPTO | J15: CANTIDAD | K15: TOTAL
B16: 44659 | C16: 0.29166667 | D16: 0.70416667 | E16: =D16-C16 -> 0.4125 | F16: =E16-$C$5 -> 0.0375 | K16: =Tabla231[[#Totals],[SUB TOTAL]]-Tabla332[[#This Row],[CANTIDAD]] -> 690250
B17: 44660 | C17: 0.29166667 | D17: 0.70555556 | E17: =D17-C17 -> 0.41388889 | F17: =E17-$C$5 -> 0.038888889 | K17: =K16-Tabla332[[#This Row],[CANTIDAD]] -> 690250
B18: 44661 | E18: =D18-C18 -> 0 | F18: 0 | K18: =K17-Tabla332[[#This Row],[CANTIDAD]] -> 690250
B19: 44662 | E19: =D19-C19 -> 0 | F19: 0 | H19: FIRMA CONFORME ___________________________
B20: 44663 | C20: 0.29166667 | D20: 0.70486111 | E20: =D20-C20 -> 0.41319444 | F20: =E20-$C$5 -> 0.038194444
B21: 44664 | C21: 0.29166667 | D21: 0.74652778 | E21: =D21-C21 -> 0.45486111 | F21: =E21-$C$5 -> 0.079861111
B22: 44665 | C22: 0.29166667 | D22: 0.70833333 | E22: =D22-C22 -> 0.41666667 | F22: =E22-$C$5 -> 0.041666667
E23: =D23-C23 -> 0 | F23: 0
B24: Total | C24: =SUBTOTAL(102,Tabla130[ENTRADA]) -> 11 | E24: =SUBTOTAL(109,E8:E23) -> 4.8534722 | F24: =SUBTOTAL(109,F8:F23) -> 0.72847222
D25: HORAS SIMPLES | E25: =Tabla130[[#Totals],[TOTAL]]-Tabla130[[#Totals],[EXTRAS]] -> 4.125 | F25: HORAS
D26: HORAS EXTRAS | E26: =Tabla130[[#Totals],[EXTRAS]] -> 0.72847222 | F26: HORAS
D27: DIAS HABILES | E27: 11 | F27: DIAS
D28: SABADOS | E28: 2 | F28: DIAS
A29: No: | C29: 190 | I29: Nom. | K29: MIGUEL
A30: 06:38 16:57 | B30: 07:00 15:08 | F30: 06:27 16:54 | G30: 06:31 16:55 | H30: 06:23 16:55 | I30: 06:33 16:54 | J30: 06:40 16:56 | M30: 06:35 16:55 | N30: 06:34 17:55 | O30: 0.27430556

Sheet ALAN 
B2: CUADRO DE DIAS LABORADOS | C2: DESDE | D2: HASTA
B3: PRERIODO LABORAL
B4: NOMBRE DE EMPLEADO
B5: RANGO HORARIO | C5: 0.375 | D5: HORAS | H5: DETALLE DE QUINCENA
E7: FECHA: | F7: =TODAY() -> 44716 | H7: NOMBRE: | I7: ALAN | J7: FECHA: | K7: =TODAY() -> 44716
B8: FECHA | C8: ENTRADA | D8: SALIDA | E8: TOTAL | F8: EXTRAS | H8: CONCEPTO | I8: VALOR | J8: CANTIDAD | K8: SUB TOTAL
B9: 44651 | C9: 0.29166667 | D9: 0.72083333 | E9: =D9-C9 -> 0.42916667 | F9: =E9-$C$5 -> 0.054166667 | H9: HORA SIMPLE | I9: 4500 | J9: 96 | K9: =Tabla2314111416182368[[#This Row],[VALOR]]*Tabla2314111416182368[[#This Row],[CANTIDAD]] -> 432000
B10: 44652 | C10: 0.29166667 | D10: 0.71875 | E10: 0.80208333 | F10: 0.42708333 | H10: HORA EXTRA | I10: 6750 | J10: 22 | K10: =Tabla2314111416182368[[#This Row],[VALOR]]*Tabla2314111416182368[[#This Row],[CANTIDAD]] -> 148500
B11: 44653 | C11: 0.29166667 | D11: 0.66666667 | E11: =D11-C11 -> 0.375 | F11: =E11-$C$5 -> 0 | H11: VIATICOS | I11: 6000 | J11: 10 | K11: =Tabla2314111416182368[[#This Row],[VALOR]]*Tabla2314111416182368[[#This Row],[CANTIDAD]] -> 60000
B12: 44654 | E12: =D12-C12 -> 0 | F12: 0 | H12: PREMIO | I12: 70000 | J12: 1 | K12: =Tabla2314111416182368[[#This Row],[VALOR]]*Tabla2314111416182368[[#This Row],[CANTIDAD]] -> 70000
B13: 44655 | E13: =D13-C13 -> 0 | F13: 0 | K13: =Tabla2314111416182368[[#This Row],[VALOR]]*Tabla2314111416182368[[#This Row],[CANTIDAD]] -> 0
B14: 44656 | C14: 0.29166667 | D14: 0.70416667 | E14: =D14-C14 -> 0.4125 | F14: =E14-$C$5 -> 0.0375 | H14: Total | K14: =SUBTOTAL(109,Tabla2314111416182368[SUB TOTAL]) -> 710500
B15: 44657 | C15: 0.29166667 | D15: 0.75555556 | E15: =D15-C15 -> 0.46388889 | F15: =E15-$C$5 -> 0.088888889 | H15: DESCUENTOS
B16: 44658 | C16: 0.29166667 | D16: 0.75347222 | E16: =D16-C16 -> 0.46180556 | F16: =E16-$C$5 -> 0.086805556 | H16: FECHA | I16: CONCEPTO | J16: CANTIDAD | K16: TOTAL
B17: 44659 | C17: 0.29166667 | D17: 0.70902778 | E17: =D17-C17 -> 0.41736111 | F17: =E17-$C$5 -> 0.042361111 | H17: 44670 | I17: ADELANTO | J17: 50000 | K17: =$K$14-J17 -> 660500
B18: 44660 | C18: 0.29166667 | D18: 0.74236111 | E18: =D18-C18 -> 0.45069444 | F18: =E18-$C$5 -> 0.075694444 | K18: =K17-J18 -> 660500
B19: 44661 | E19: =D19-C19 -> 0 | F19: 0 | K19: =K18-J19 -> 660500
B20: 44662 | E20: =D20-C20 -> 0 | F20: 0 | H20: FIRMA CONFORME ___________________________
B21: 44663 | C21: 0.29166667 | D21: 0.5 | E21: =D21-C21 -> 0.20833333 | F21: 0
B22: 44664 | C22: 0.29166667 | D22: 0.76736111 | E22: =D22-C22 -> 0.47569444 | F22: =E22-$C$5 -> 0.10069444
B23: 44665 | C23: 0.29166667 | D23: 0.70833333 | E23: =D23-C23 -> 0.41666667 | F23: =E23-$C$5 -> 0.041666667
E24: =D24-C24 -> 0 | F24: 0
B25: Total | C25: =SUBTOTAL(102,Tabla1304170[ENTRADA]) -> 11 | E25: =SUBTOTAL(109,E9:E24) -> 4.9131944 | F25: =SUBTOTAL(109,Tabla1304170[EXTRAS]) -> 0.95486111
D26: HORAS SIMPLES | E26: =Tabla1304170[[#Totals],[TOTAL]]-Tabla1304170[[#Totals],[EXTRAS]] -> 3.9583333 | F26: HORAS
D27: HORAS EXTRAS | E27: =Tabla1304170[[#Totals],[EXTRAS]] -> 0.95486111 | F27: HORAS
D28: DIAS HABILES | E28: 11 | F28: DIAS
D29: SABADOS | E29: 0 | F29: DIAS
A30: No: | C30: 100 | I30: Nom. | K30: ALAM
A31: 06:38 17:18 | B31: 07:00 17:15 | F31: 06:16 16:54 | G31: 06:23 18:08 | H31: 07:49 18:05 | I31: 06:49 17:01 | J31: 06:54 17:49 | M31: 0.28333333 | N31: 06:46 18:25 | O31: 0.30833333

Sheet EZEQUIEL
B2: CUADRO DE DIAS LABORADOS | C2: DESDE | D2: HASTA
B3: PRERIODO LABORAL
B4: NOMBRE DE EMPLEADO
B5: RANGO HORARIO | C5: 0.375 | D5: HORAS | H5: DETALLE DE QUINCENA
E7: FECHA: | F7: =TODAY() -> 44716 | H7: NOMBRE: | I7: EZEQUIEL | J7: FECHA: | K7: =TODAY() -> 44716
B8: FECHA | C8: ENTRADA | D8: SALIDA | E8: TOTAL | F8: EXTRAS | H8: CONCEPTO | I8: VALOR | J8: CANTIDAD | K8: SUB TOTAL
B9: 44651 | C9: 0.29305556 | D9: 0.72222222 | E9: =D9-C9 -> 0.42916667 | F9: =Tabla13041[[#This Row],[TOTAL]]-$C$5 -> 0.054166667 | H9: HORA SIMPLE | I9: 4500 | J9: 90 | K9: =Tabla23141114161823[[#This Row],[VALOR]]*Tabla23141114161823[[#This Row],[CANTIDAD]] -> 405000
B10: 44652 | C10: 0.29236111 | D10: 0.71527778 | E10: 0.79791667 | F10: 0.42291667 | H10: HORA EXTRA | I10: 8358.13 | J10: 13 | K10: =Tabla23141114161823[[#This Row],[VALOR]]*Tabla23141114161823[[#This Row],[CANTIDAD]] -> 108655.69
B11: 44653 | C11: 0.29166667 | D11: 0.66666667 | E11: =D11-C11 -> 0.375 | F11: =Tabla13041[[#This Row],[TOTAL]]-$C$5 -> 0 | H11: VIATICOS | I11: 6000 | J11: 9 | K11: =Tabla23141114161823[[#This Row],[VALOR]]*Tabla23141114161823[[#This Row],[CANTIDAD]] -> 54000
B12: 44654 | E12: =D12-C12 -> 0 | F12: 0 | H12: PREMIO | I12: 10447.64 | J12: 10 | K12: =Tabla23141114161823[[#This Row],[VALOR]]*Tabla23141114161823[[#This Row],[CANTIDAD]] -> 104476.4
B13: 44655 | E13: =D13-C13 -> 0 | F13: 0 | K13: =Tabla23141114161823[[#This Row],[VALOR]]*Tabla23141114161823[[#This Row],[CANTIDAD]] -> 0
B14: 44656 | C14: 0.30416667 | D14: 0.66666667 | E14: =D14-C14 -> 0.3625 | F14: =Tabla13041[[#This Row],[TOTAL]]-$C$5 -> -0.0125 | H14: Total | K14: =SUBTOTAL(109,Tabla23141114161823[SUB TOTAL]) -> 672132.09
B15: 44657 | C15: 0.29652778 | D15: 0.67708333 | E15: =D15-C15 -> 0.38055556 | F15: =Tabla13041[[#This Row],[TOTAL]]-$C$5 -> 0.0055555556 | H15: DESCUENTOS
B16: 44658 | E16: =D16-C16 -> 0 | F16: 0 | H16: FECHA | I16: CONCEPTO | J16: CANTIDAD | K16: TOTAL
B17: 44659 | C17: 0.29791667 | D17: 0.70972222 | E17: =D17-C17 -> 0.41180556 | F17: =Tabla13041[[#This Row],[TOTAL]]-$C$5 -> 0.036805556 | H17: 44670 | I17: ADELANTO | K17: =$K$14-J17 -> 672132.09
B18: 44660 | C18: 0.30277778 | D18: 0.67916667 | E18: =D18-C18 -> 0.37638889 | F18: =Tabla13041[[#This Row],[TOTAL]]-$C$5 -> 0.0013888889 | K18: =K17-J18 -> 672132.09
B19: 44661 | E19: =D19-C19 -> 0 | F19: 0 | K19: =K18-J19 -> 672132.09
B20: 44662 | E20: =D20-C20 -> 0 | F20: 0 | H20: FIRMA CONFORME ___________________________
B21: 44663 | C21: 0.30069444 | D21: 0.71527778 | E21: =D21-C21 -> 0.41458333 | F21: =Tabla13041[[#This Row],[TOTAL]]-$C$5 -> 0.039583333
B22: 44664 | C22: 0.29930556 | D22: 0.66666667 | E22: =D22-C22 -> 0.36736111 | F22: =Tabla13041[[#This Row],[TOTAL]]-$C$5 -> -0.0076388889
B23: 44665 | C23: 0.30277778 | D23: 0.66666667 | E23: =D23-C23 -> 0.36388889 | F23: =Tabla13041[[#This Row],[TOTAL]]-$C$5 -> -0.011111111
E24: =D24-C24 -> 0 | F24: 0 | H24: Fede: El premio es de lunes a a viernes
B25: Total | C25: =SUBTOTAL(102,Tabla13041[ENTRADA]) -> 10 | E25: =SUBTOTAL(109,E9:E24) -> 4.2791667 | F25: =SUBTOTAL(109,Tabla13041[EXTRAS]) -> 0.52916667 | H25: Fede: Incluyendo los feriados
D26: HORAS SIMPLES | E26: =Tabla13041[[#Totals],[TOTAL]]-Tabla13041[[#Totals],[EXTRAS]] -> 3.75 | F26: HORAS
D27: HORAS EXTRAS | E27: =Tabla13041[[#Totals],[EXTRAS]] -> 0.52916667 | F27: HORAS
D28: DIAS HABILES | E28: 11 | F28: DIAS
D29: SABADOS | E29: 0 | F29: DIAS
A30: No: | C30: 28 | I30: Nom. | K30: EZEQUIEL
A31: 07:02 17:20 | B31: 07:01 17:10 | F31: 0.30416667 | G31: 07:07 16:15 | I31: 07:09 17:02 | J31: 07:16 16:18 | M31: 07:13 17:10 | N31: 0.29930556 | O31: 0.30277778

Sheet JUNIOR
B2: CUADRO DE DIAS LABORADOS
B3: PRERIODO LABORAL
B4: NOMBRE DE EMPLEADO | H4: DETALLE DE QUINCENA
B5: RANGO HORARIO | C5: 0.375 | D5: HORAS
E6: FECHA: | F6: =TODAY() -> 44716 | H6: NOMBRE: | I6: JUNIOR | J6: FECHA: | K6: =TODAY() -> 44716
B7: FECHA | C7: ENTRADA | D7: SALIDA | E7: TOTAL | F7: EXTRAS | H7: CONCEPTO | I7: VALOR | J7: CANTIDAD | K7: SUB TOTAL
B8: 44651 | E8: =D8-C8 -> 0 | F8: 0 | H8: HORA SIMPLE | I8: 4500 | J8: 33 | K8: =Tabla2314119[[#This Row],[VALOR]]*Tabla2314119[[#This Row],[CANTIDAD]] -> 148500
B9: 44652 | E9: =D9-C9 -> 0 | F9: 0 | H9: HORA EXTRA | I9: 6750 | J9: 1 | K9: =Tabla2314119[[#This Row],[VALOR]]*Tabla2314119[[#This Row],[CANTIDAD]] -> 6750
B10: 44653 | E10: =D10-C10 -> 0 | F10: 0 | H10: VIATICOS | I10: 6000 | J10: 2 | K10: =Tabla2314119[[#This Row],[VALOR]]*Tabla2314119[[#This Row],[CANTIDAD]] -> 12000
B11: 44654 | E11: =D11-C11 -> 0 | F11: 0 | H11: PREMIO | I11: 70000 | K11: =Tabla2314119[[#This Row],[VALOR]]*Tabla2314119[[#This Row],[CANTIDAD]] -> 0
B12: 44655 | E12: =D12-C12 -> 0 | F12: 0 | K12: =Tabla2314119[[#This Row],[VALOR]]*Tabla2314119[[#This Row],[CANTIDAD]] -> 0
B13: 44656 | E13: =D13-C13 -> 0 | F13: 0 | H13: Total | K13: =SUBTOTAL(109,Tabla2314119[SUB TOTAL]) -> 167250
B14: 44657 | E14: =D14-C14 -> 0 | F14: 0 | H14: DESCUENTOS
B15: 44658 | E15: =D15-C15 -> 0 | F15: 0 | H15: FECHA | I15: CONCEPTO | J15: CANTIDAD | K15: TOTAL
B16: 44659 | C16: 0.29166667 | D16: 0.70833333 | E16: =D16-C16 -> 0.41666667 | F16: =Tabla1303521[[#This Row],[TOTAL]]-$C$5 -> 0.041666667 | J16: 0 | K16: =Tabla2314119[[#Totals],[SUB TOTAL]]-Tabla332101312[[#This Row],[CANTIDAD]] -> 167250
B17: 44660 | C17: 0.29166667 | D17: 0.54166667 | E17: =D17-C17 -> 0.25 | F17: 0 | K17: =K16-Tabla332101312[[#This Row],[CANTIDAD]] -> 167250
B18: 44661 | E18: =D18-C18 -> 0 | F18: 0 | K18: =K17-Tabla332101312[[#This Row],[CANTIDAD]] -> 167250
B19: 44662 | E19: =D19-C19 -> 0 | F19: 0 | H19: FIRMA CONFORME ___________________________
B20: 44663 | C20: 0.29166667 | D20: 0.54166667 | E20: =D20-C20 -> 0.25 | F20: 0
B21: 44664 | C21: 0.29166667 | D21: 0.54166667 | E21: =D21-C21 -> 0.25 | F21: 0
B22: 44665 | C22: 0.29166667 | D22: 0.54166667 | E22: =D22-C22 -> 0.25 | F22: 0
E23: =D23-C23 -> 0 | F23: 0
B24: Total | E24: =SUBTOTAL(109,E8:E23) -> 1.4166667 | F24: =SUBTOTAL(109,Tabla1303521[EXTRAS]) -> 0.041666667
D25: HORAS SIMPLES | E25: =Tabla1303521[[#Totals],[TOTAL]]-Tabla1303521[[#Totals],[EXTRAS]] -> 1.375 | F25: HORAS
D26: HORAS EXTRAS | E26: =Tabla1303521[[#Totals],[EXTRAS]] -> 0.041666667 | F26: HORAS
D27: DIAS HABILES | E27: 11 | F27: DIAS
A28: No: | C28: 29 | I28: Nom. | K28: CESAR
A29: 07:09 18:00 | E29: 06:35 17:16 | K29: 06:59 17:01 | L29: 07:06 16:49 | O29: 07:00 16:54 | P29: 0.29513889

Sheet JOSE 
B2: CUADRO DE DIAS LABORADOS | C2: DESDE | D2: HASTA
B3: PRERIODO LABORAL
B4: NOMBRE DE EMPLEADO
B5: RANGO HORARIO | C5: 0.375 | D5: HORAS | H5: DETALLE DE QUINCENA
E7: FECHA: | F7: =TODAY() -> 44716 | H7: NOMBRE: | I7: JOSE | J7: FECHA: | K7: =TODAY() -> 44716
B8: FECHA | C8: ENTRADA | D8: SALIDA | E8: TOTAL | F8: EXTRAS | H8: CONCEPTO | I8: VALOR | J8: CANTIDAD | K8: SUB TOTAL
B9: 44651 | C9: 0.27638889 | D9: 0.76111111 | E9: =D9-C9 -> 0.48472222 | F9: =E9-$C$5 -> 0.10972222 | H9: MES DE ABRIL | I9: 1800000 | K9: =Tabla231411141618231159[[#This Row],[VALOR]]*Tabla231411141618231159[[#This Row],[CANTIDAD]] -> 0
B10: 44652 | C10: 0.2875 | D10: 0.70694444 | E10: =D10-C10 -> 0.41944444 | F10: =E10-$C$5 -> 0.044444444 | H10: 1ra QUINCENA | I10: 900000 | J10: 1 | K10: =Tabla231411141618231159[[#This Row],[VALOR]]*Tabla231411141618231159[[#This Row],[CANTIDAD]] -> 900000
B11: 44653 | C11: 0.29166667 | D11: 0.66666667 | E11: =D11-C11 -> 0.375 | F11: =E11-$C$5 -> 0 | K11: =Tabla231411141618231159[[#This Row],[VALOR]]*Tabla231411141618231159[[#This Row],[CANTIDAD]] -> 0
B12: 44654 | C12: 0.27152778 | D12: 0.58333333 | E12: =D12-C12 -> 0.31180556 | F12: =E12-$C$5 -> -0.063194444 | K12: =Tabla231411141618231159[[#This Row],[VALOR]]*Tabla231411141618231159[[#This Row],[CANTIDAD]] -> 0
B13: 44655 | E13: =D13-C13 -> 0 | F13: 0 | K13: =Tabla231411141618231159[[#This Row],[VALOR]]*Tabla231411141618231159[[#This Row],[CANTIDAD]] -> 0
B14: 44656 | C14: 0.27847222 | D14: 0.70694444 | E14: =D14-C14 -> 0.42847222 | F14: =E14-$C$5 -> 0.053472222 | H14: Total | K14: =SUBTOTAL(109,Tabla231411141618231159[SUB TOTAL]) -> 900000
B15: 44657 | C15: 0.27638889 | E15: 0 | F15: 0 | H15: DESCUENTOS
B16: 44658 | C16: 0.27638889 | D16: 0.70833333 | E16: =D16-C16 -> 0.43194444 | F16: =E16-$C$5 -> 0.056944444 | H16: FECHA | I16: CONCEPTO | J16: CANTIDAD | K16: TOTAL
B17: 44659 | C17: 0.27916667 | D17: 0.75069444 | E17: =D17-C17 -> 0.47152778 | F17: =E17-$C$5 -> 0.096527778 | H17: 44670 | I17: ADELANTO | J17: 500000 | K17: =$K$14-J17 -> 400000
B18: 44660 | C18: 0.26736111 | E18: 0 | F18: 0 | K18: =K17-J18 -> 400000
B19: 44661 | C19: 0.2875 | D19: 0.52916667 | E19: =D19-C19 -> 0.24166667 | F19: =E19-$C$5 -> -0.13333333 | K19: =K18-J19 -> 400000
B20: 44662 | E20: =D20-C20 -> 0 | F20: 0 | H20: FIRMA CONFORME ___________________________
B21: 44663 | C21: 0.26180556 | D21: 0.71319444 | E21: =D21-C21 -> 0.45138889 | F21: =E21-$C$5 -> 0.076388889
B22: 44664 | C22: 0.27638889 | D22: 0.71319444 | E22: =D22-C22 -> 0.43680556 | F22: =E22-$C$5 -> 0.061805556
B23: 44665 | C23: 0.31111111 | D23: 0.70833333 | E23: =D23-C23 -> 0.39722222 | F23: =E23-$C$5 -> 0.022222222
E24: =D24-C24 -> 0 | F24: 0
B25: Total | C25: =SUBTOTAL(102,Tabla130413571[ENTRADA]) -> 13 | E25: =SUBTOTAL(109,E9:E24) -> 4.45 | F25: =SUBTOTAL(109,Tabla130413571[EXTRAS]) -> 0.325
D26: HORAS SIMPLES | E26: =Tabla130413571[[#Totals],[TOTAL]]-Tabla130413571[[#Totals],[EXTRAS]] -> 4.125 | F26: HORAS
D27: HORAS EXTRAS | E27: =Tabla130413571[[#Totals],[EXTRAS]] -> 0.325 | F27: HORAS
D28: DIAS HABILES | E28: 11 | F28: DIAS
A29: No: | C29: 200 | I29: Nom. | K29: JOSE
A30: 06:38 18:16 | B30: 06:54 16:58 | D30: 0.27152778 | F30: 06:41 16:58 | G30: 0.27638889 | H30: 06:38 17:00 | I30: 06:42 18:01 | J30: 0.26736111 | K30: 06:54 12:42 | M30: 06:17 17:07 | N30: 06:38 17:07 | O30: 0.31111111

Sheet KEVIN
B2: CUADRO DE DIAS LABORADOS | C2: DESDE | D2: HASTA
B3: PRERIODO LABORAL
B4: NOMBRE DE EMPLEADO
B5: RANGO HORARIO | C5: 0.375 | D5: HORAS | H5: DETALLE DE QUINCENA
E6: FECHA: | F6: =TODAY() -> 44716
B7: FECHA | C7: ENTRADA | D7: SALIDA | E7: TOTAL | F7: EXTRAS | H7: NOMBRE: | I7: KEVIN | J7: FECHA: | K7: =TODAY() -> 44716
B8: 44651 | C8: 0.29166667 | D8: 0.50833333 | E8: =D8-C8 -> 0.21666667 | F8: 0 | H8: CONCEPTO | I8: VALOR | J8: CANTIDAD | K8: SUB TOTAL
B9: 44652 | C9: 0.29166667 | D9: 0.70833333 | E9: 0.79166667 | F9: 0.41666667 | H9: HORA SIMPLE | I9: 3700 | J9: 70 | K9: =Tabla2314111416[[#This Row],[VALOR]]*Tabla2314111416[[#This Row],[CANTIDAD]] -> 259000
B10: 44653 | C10: 0.29166667 | D10: 0.66666667 | E10: =D10-C10 -> 0.375 | F10: =E10-$C$5 -> 0 | H10: HORA EXTRA | I10: 5550 | J10: 13 | K10: =Tabla2314111416[[#This Row],[VALOR]]*Tabla2314111416[[#This Row],[CANTIDAD]] -> 72150
B11: 44654 | E11: =D11-C11 -> 0 | F11: 0 | H11: VIATICO | I11: 4000 | J11: 7 | K11: =Tabla2314111416[[#This Row],[VALOR]]*Tabla2314111416[[#This Row],[CANTIDAD]] -> 28000
B12: 44655 | E12: =D12-C12 -> 0 | F12: 0 | H12: PREMIO | I12: 70000 | K12: =Tabla2314111416[[#This Row],[VALOR]]*Tabla2314111416[[#This Row],[CANTIDAD]] -> 0
B13: 44656 | E13: =D13-C13 -> 0 | F13: 0 | K13: =Tabla2314111416[[#This Row],[VALOR]]*Tabla2314111416[[#This Row],[CANTIDAD]] -> 0
B14: 44657 | C14: 0.29166667 | D14: 0.70625 | E14: =D14-C14 -> 0.41458333 | F14: =E14-$C$5 -> 0.039583333 | H14: Total | K14: =SUBTOTAL(109,Tabla2314111416[SUB TOTAL]) -> 359150
B15: 44658 | C15: 0.29166667 | D15: 0.70833333 | E15: =D15-C15 -> 0.41666667 | F15: =E15-$C$5 -> 0.041666667 | H15: DESCUENTOS
B16: 44659 | C16: 0.29166667 | D16: 0.70625 | E16: =D16-C16 -> 0.41458333 | F16: =E16-$C$5 -> 0.039583333 | H16: FECHA | I16: CONCEPTO | J16: CANTIDAD | K16: TOTAL
B17: 44660 | E17: =D17-C17 -> 0 | F17: 0 | K17: =K14-J17 -> 359150
B18: 44661 | E18: =D18-C18 -> 0 | F18: 0 | J18: 0 | K18: =K17-J18 -> 359150
B19: 44662 | E19: =D19-C19 -> 0 | F19: 0 | K19: =K18-J19 -> 359150
B20: 44663 | C20: 0.29166667 | D20: 0.70763889 | E20: =D20-C20 -> 0.41597222 | F20: =E20-$C$5 -> 0.040972222
B21: 44664 | C21: 0.29166667 | D21: 0.70833333 | E21: =D21-C21 -> 0.41666667 | F21: =E21-$C$5 -> 0.041666667
B22: 44665 | E22: =D22-C22 -> 0 | F22: 0
E23: =D23-C23 -> 0 | F23: 0
B24: Total | C24: =SUBTOTAL(102,Tabla130[ENTRADA]) -> 11 | E24: =SUBTOTAL(109,E8:E23) -> 3.4618056 | F24: =SUBTOTAL(109,Tabla13038[EXTRAS]) -> 0.62013889
D25: HORAS SIMPLES | E25: =Tabla13038[[#Totals],[TOTAL]]-Tabla13038[[#Totals],[EXTRAS]] -> 2.8416667 | F25: HORAS
D26: HORAS EXTRAS | E26: =Tabla13038[[#Totals],[EXTRAS]] -> 0.62013889 | F26: HORAS
D27: DIAS HABILES | E27: 11 | F27: DIAS
D28: SABADOS | E28: 2 | F28: DIAS
A29: No: | C29: 31 | I29: Nom. | K29: KEVIN
A30: 06:48 12:12 | B30: 06:37 17:00 | G30: 06:20 16:57 | H30: 06:47 17:00 | I30: 06:36 16:57 | M30: 06:36 16:59 | N30: 06:38 17:00

Sheet RENZO
B2: CUADRO DE DIAS LABORADOS | C2: DESDE | D2: HASTA
B3: PRERIODO LABORAL
B4: NOMBRE DE EMPLEADO
B5: RANGO HORARIO | C5: 0.375 | D5: HORAS | H5: DETALLE DE QUINCENA
E7: FECHA: | F7: =TODAY() -> 44716 | H7: NOMBRE: | I7: RENZO | J7: FECHA: | K7: =TODAY() -> 44716
B8: FECHA | C8: ENTRADA | D8: SALIDA | E8: TOTAL | F8: EXTRAS | H8: CONCEPTO | I8: VALOR | J8: CANTIDAD | K8: SUB TOTAL
B9: 44651 | C9: 0.29236111 | D9: 0.72222222 | E9: =D9-C9 -> 0.42986111 | F9: =E9-$C$5 -> 0.054861111 | H9: HORA SIMPLE | I9: 3700 | J9: 47 | K9: =Tabla2314111416182311[[#This Row],[VALOR]]*Tabla2314111416182311[[#This Row],[CANTIDAD]] -> 173900
B10: 44652 | C10: 0.29236111 | D10: 0.71527778 | E10: 0.79791667 | F10: 0.42291667 | H10: HORA EXTRA | I10: 5550 | J10: 14 | K10: =Tabla2314111416182311[[#This Row],[VALOR]]*Tabla2314111416182311[[#This Row],[CANTIDAD]] -> 77700
B11: 44653 | C11: 0.29166667 | D11: 0.66666667 | E11: =D11-C11 -> 0.375 | F11: =E11-$C$5 -> 0 | H11: VIATICOS | I11: 4000 | J11: 5 | K11: =Tabla2314111416182311[[#This Row],[VALOR]]*Tabla2314111416182311[[#This Row],[CANTIDAD]] -> 20000
B12: 44654 | E12: =D12-C12 -> 0 | F12: 0 | H12: PREMIO | I12: 70000 | K12: =Tabla2314111416182311[[#This Row],[VALOR]]*Tabla2314111416182311[[#This Row],[CANTIDAD]] -> 0
B13: 44655 | E13: =D13-C13 -> 0 | F13: 0 | H13: PRODUCCION | K13: =Tabla2314111416182311[[#This Row],[VALOR]]*Tabla2314111416182311[[#This Row],[CANTIDAD]] -> 0
B14: 44656 | E14: =D14-C14 -> 0 | F14: 0 | H14: Total | K14: =SUBTOTAL(109,Tabla2314111416182311[SUB TOTAL]) -> 271600
B15: 44657 | C15: 0.29652778 | D15: 0.70694444 | E15: =D15-C15 -> 0.41041667 | F15: =E15-$C$5 -> 0.035416667 | H15: DESCUENTOS
B16: 44658 | C16: 0.30555556 | D16: 0.74791667 | E16: =D16-C16 -> 0.44236111 | F16: =E16-$C$5 -> 0.067361111 | H16: FECHA | I16: CONCEPTO | J16: CANTIDAD | K16: TOTAL
B17: 44659 | C17: 0.29513889 | D17: 0.39930556 | E17: =D17-C17 -> 0.10416667 | F17: 0 | K17: =$K$14-J17 -> 271600
B18: 44660 | E18: =D18-C18 -> 0 | F18: 0 | K18: =K17-J18 -> 271600
B19: 44661 | E19: =D19-C19 -> 0 | F19: 0 | K19: =K18-J19 -> 271600
B20: 44662 | E20: =D20-C20 -> 0 | F20: 0 | H20: FIRMA CONFORME ___________________________
B21: 44663 | E21: =D21-C21 -> 0 | F21: 0
B22: 44664 | E22: =D22-C22 -> 0 | F22: 0
B23: 44665 | E23: =D23-C23 -> 0 | F23: 0
E24: =D24-C24 -> 0 | F24: 0
B25: Total | C25: =SUBTOTAL(102,Tabla1304135[ENTRADA]) -> 6 | E25: =SUBTOTAL(109,E9:E24) -> 2.5597222 | F25: =SUBTOTAL(109,Tabla1304135[EXTRAS]) -> 0.58055556
D26: HORAS SIMPLES | E26: =Tabla1304135[[#Totals],[TOTAL]]-Tabla1304135[[#Totals],[EXTRAS]] -> 1.9791667 | F26: HORAS
D27: HORAS EXTRAS | E27: =Tabla1304135[[#Totals],[EXTRAS]] -> 0.58055556 | F27: HORAS
D28: DIAS HABILES | E28: 11 | F28: DIAS
A29: No: | C29: 32 | I29: Nom. | K29: RENZO
A30: 07:01 17:20 | B30: 07:01 17:10 | G30: 07:07 16:58 | H30: 07:20 17:57 17:58 | I30: 07:05 09:35

Sheet SN
B7: Columna1 | C7: Columna2 | D7: Columna3 | E7: Columna4 | F7: Columna5
B8: 44895 | E8: =D8-C8 -> 0 | F8: 0
B9: 44896 | E9: =D9-C9 -> 0 | F9: 0
B10: 44897 | C10: 0.29652778 | D10: 0.70694444 | E10: =D10-C10 -> 0.41041667 | F10: =E10-$C$5 -> 0.41041667
B11: 44898 | C11: 0.29166667 | D11: 0.71458333 | E11: =D11-C11 -> 0.42291667 | F11: =E11-$C$5 -> 0.42291667
B12: 44899 | C12: 0.29166667 | D12: 0.70763889 | E12: =D12-C12 -> 0.41597222 | F12: =E12-$C$5 -> 0.41597222
B13: 44900 | C13: 0.29166667 | D13: 0.7125 | E13: =D13-C13 -> 0.42083333 | F13: =E13-$C$5 -> 0.42083333
B14: 44901 | C14: 0.29166667 | D14: 0.71041667 | E14: =D14-C14 -> 0.41875 | F14: =E14-$C$5 -> 0.41875
B15: 44902 | E15: =D15-C15 -> 0 | F15: 0
B16: 44903 | E16: =D16-C16 -> 0 | F16: 0
B17: 44904 | C17: 0.29166667 | D17: 0.70902778 | E17: =D17-C17 -> 0.41736111 | F17: =E17-$C$5 -> 0.41736111
B18: 44905 | C18: 0.29166667 | D18: 0.70833333 | E18: =D18-C18 -> 0.41666667 | F18: =E18-$C$5 -> 0.41666667
B19: 44906 | C19: 0.29166667 | D19: 0.7125 | E19: =D19-C19 -> 0.42083333 | F19: =E19-$C$5 -> 0.42083333
B20: 44907 | C20: 0.29166667 | D20: 0.71875 | E20: =D20-C20 -> 0.42708333 | F20: =E20-$C$5 -> 0.42708333
B21: 44908 | C21: 0.29166667 | D21: 0.66875 | E21: =D21-C21 -> 0.37708333 | F21: =E21-$C$5 -> 0.37708333
B22: 44909 | E22: =D22-C22 -> 0 | F22: =E22-$C$5 -> 0
B23: 44910 | E23: =D23-C23 -> 0 | F23: =E23-$C$5 -> 0
B24: 44911 | E24: =D24-C24 -> 0 | F24: =E24-$C$5 -> 0
B25: 44912 | E25: =D25-C25 -> 0 | F25: =E25-$C$5 -> 0
B26: 44913 | E26: =D26-C26 -> 0 | F26: =E26-$C$5 -> 0
E27: =D27-C27 -> 0 | F27: =E27-$C$5 -> 0
E28: =D28-C28 -> 0 | F28: =E28-$C$5 -> 0
E29: =D29-C29 -> 0 | F29: =E29-$C$5 -> 0
E30: =D30-C30 -> 0 | F30: =E30-$C$5 -> 0
E31: =D31-C31 -> 0 | F31: 0
E32: =D32-C32 -> 0 | F32: 0
B33: Total | E33: =SUBTOTAL(109,E8:E32) -> 4.1479167 | F33: =SUBTOTAL(109,Tabla13039[Columna5]) -> 4.1479167

Sheet IMPRIMIR
A2: ='LEO SOTO'!H6 -> DETALLE DE QUINCENA | F2: DETALLE DE QUINCENA | K2: DETALLE DE QUINCENA
A4: ='LEO SOTO'!H8 -> NOMBRE: | B4: ='LEO SOTO'!I8 -> LEO | C4: ='LEO SOTO'!J8 -> FECHA: | D4: ='LEO SOTO'!K8 -> 44716 | F4: NOMBRE: | G4: GABRIEL | H4: FECHA: | I4: =GABRIEL!J8 -> 44716 | K4: NOMBRE: | L4: MIGUEL | M4: FECHA: | N4: =MIGUEL!K6 -> 44716
A5: CONCEPTO | B5: VALOR | C5: CANTIDAD | D5: SUB TOTAL | F5: CONCEPTO | G5: VALOR | H5: CANTIDAD | I5: SUB TOTAL | K5: CONCEPTO | L5: VALOR | M5: CANTIDAD | N5: SUB TOTAL
A6: HORA SIMP | B6: 5000 | C6: ='LEO SOTO'!J10 -> 11 | D6: ='LEO SOTO'!K10 -> 55000 | F6: =GABRIEL!G10 -> HORA SIMPLE | G6: =GABRIEL!H10 -> 5000 | H6: =GABRIEL!I10 -> 11 | I6: =GABRIEL!J10 -> 55000 | K6: =MIGUEL!H8 -> HORA SIMPLE | L6: =MIGUEL!I8 -> 4500 | M6: =MIGUEL!J8 -> 99 | N6: =MIGUEL!K8 -> 445500
A7: HORA EXT | B7: ='LEO SOTO'!I11 -> 7500 | C7: ='LEO SOTO'!J11 -> 30 | D7: ='LEO SOTO'!K11 -> 225000 | F7: =GABRIEL!G11 -> HORA EXTRA | G7: =GABRIEL!H11 -> 7500 | H7: =GABRIEL!I11 -> 33 | I7: =GABRIEL!J11 -> 247500 | K7: =MIGUEL!H9 -> HORA EXTRA | L7: =MIGUEL!I9 -> 6750 | M7: =MIGUEL!J9 -> 17 | N7: =MIGUEL!K9 -> 114750
A8: ='LEO SOTO'!H12 -> HORA RECIBO | B8: ='LEO SOTO'!I12 -> 4313.43 | C8: ='LEO SOTO'!J12 -> 88 | D8: ='LEO SOTO'!K12 -> 323897 | F8: =GABRIEL!G12 -> HORA DE RECIBO | G8: 4313.43 | H8: =GABRIEL!I12 -> 88 | I8: =GABRIEL!J12 -> 308619 | K8: =MIGUEL!H10 -> VIATICOS | L8: =MIGUEL!I10 -> 6000 | M8: =MIGUEL!J10 -> 10 | N8: =MIGUEL!K10 -> 60000
A9: VIATICOS | B9: ='LEO SOTO'!I13 -> 6000 | C9: ='LEO SOTO'!J13 -> 11 | D9: ='LEO SOTO'!K13 -> 66000 | F9: =GABRIEL!G13 -> VIATICOS | G9: =GABRIEL!H13 -> 6000 | H9: =GABRIEL!I13 -> 12 | I9: =GABRIEL!J13 -> 72000 | K9: =MIGUEL!H11 -> PREMIO | L9: =MIGUEL!I11 -> 70000 | M9: =MIGUEL!J11 -> 1 | N9: =MIGUEL!K11 -> 70000
A10: CATEGORIA | B10: ='LEO SOTO'!I14 -> 50000 | C10: ='LEO SOTO'!J14 -> 1 | D10: ='LEO SOTO'!K14 -> 50000 | F10: =GABRIEL!G14 -> CATEGORIA | G10: =GABRIEL!H14 -> 35000 | H10: =GABRIEL!I14 -> 1 | I10: =GABRIEL!J14 -> 35000 | L10: =MIGUEL!I12 -> 0 | M10: =MIGUEL!J12 -> 0 | N10: =MIGUEL!K12 -> 0
A11: PREMIO | B11: ='LEO SOTO'!I15 -> 90000 | C11: ='LEO SOTO'!J15 -> 1 | D11: ='LEO SOTO'!K15 -> 90000 | F11: =GABRIEL!G15 -> PREMIO | G11: =GABRIEL!H15 -> 90000 | H11: 1 | I11: =GABRIEL!J15 -> 90000 | K11: Total | N11: =SUBTOTAL(109,Tabla23142[SUB TOTAL]) -> 690250
B12: ='LEO SOTO'!I16 -> 0 | D12: ='LEO SOTO'!K16 -> 0 | G12: =GABRIEL!H16 -> 0 | H12: 1 | I12: =GABRIEL!J16 -> 0 | K12: DESCUENTOS
A13: Total | D13: =SUBTOTAL(109,Tabla2726[SUB TOTAL]) -> 809897 | F13: Total | I13: =SUBTOTAL(109,Tabla27229[SUB TOTAL]) -> 808119 | K13: FECHA | L13: CONCEPTO | M13: CANTIDAD | N13: TOTAL
A14: DESCUENTOS | F14: DESCUENTOS | M14: =MIGUEL!J16 -> 0 | N14: =MIGUEL!K16 -> 690250
A15: FECHA | B15: CONCEPTO | C15: CANTIDAD | D15: TOTAL | F15: FECHA | G15: CONCEPTO | H15: CANTIDAD | I15: TOTAL | M15: =MIGUEL!J17 -> 0 | N15: =MIGUEL!K17 -> 690250
A16: 44670 | B16: DEPOSITO RC | C16: ='LEO SOTO'!J20 -> 323897 | D16: ='LEO SOTO'!K20 -> 486000 | F16: 44670 | G16: DEPOSITO RC | H16: =GABRIEL!I20 -> 308619 | I16: =GABRIEL!J20 -> 499500 | M16: =MIGUEL!J18 -> 0 | N16: =MIGUEL!K18 -> 690250
B17: PRESTAMO | C17: 100000 | D17: ='LEO SOTO'!K21 -> 386000 | G17: ADELANTO | H17: =GABRIEL!I21 -> 410375 | I17: =GABRIEL!J21 -> 89125 | K17: FIRMA CONFORME __________________
B18: ADELANTO | C18: ='LEO SOTO'!J22 -> 200000 | D18: ='LEO SOTO'!K22 -> 186000 | I18: =GABRIEL!J23 -> 89125
D19: ='LEO SOTO'!K23 -> 186000 | I19: =GABRIEL!J22 -> 89125
D20: ='LEO SOTO'!K24 -> 186000 | I20: =GABRIEL!J23 -> 89125
F21: FIRMA CONFORME _______________________$
K25: DETALLE DE QUINCENA
K27: NOMBRE: | L27: walter | M27: FECHA: | N27: =WALTER!K6 -> 44716
A28: DETALLE DE QUINCENA | F28: DETALLE DE QUINCENA | K28: CONCEPTO | L28: VALOR | M28: CANTIDAD | N28: SUB TOTAL
K29: =WALTER!H8 -> HORA SIMPLE | L29: =WALTER!I8 -> 5000 | M29: =WALTER!J8 -> 99 | N29: =WALTER!K8 -> 495000
A30: NOMBRE: | B30: EZEQUIEL | C30: FECHA: | D30: =EZEQUIEL!K7 -> 44716 | F30: NOMBRE: | G30: JOSE | H30: FECHA: | I30: =RENZO!K7 -> 44716 | K30: =WALTER!H9 -> HORA EXTRA | L30: =WALTER!I9 -> 7500 | M30: =WALTER!J9 -> 30 | N30: =WALTER!K9 -> 225000
A31: CONCEPTO | B31: VALOR | C31: CANTIDAD | D31: SUB TOTAL | F31: CONCEPTO | G31: VALOR | H31: CANTIDAD | I31: SUB TOTAL | K31: =WALTER!H10 -> VIATICOS | L31: =WALTER!I10 -> 6000 | M31: =WALTER!J10 -> 11 | N31: =WALTER!K10 -> 66000
A32: HORA SIMPLE | B32: =EZEQUIEL!I9 -> 4500 | C32: =EZEQUIEL!J9 -> 90 | D32: =EZEQUIEL!K9 -> 405000 | F32: ='JOSE '!H9 -> MES DE ABRIL | G32: ='JOSE '!I9 -> 1800000 | H32: ='JOSE '!J9 -> 0 | K32: =WALTER!H11 -> PREMIO | L32: =WALTER!I11 -> 70000 | M32: =WALTER!J11 -> 1 | N32: =WALTER!K11 -> 70000
A33: HORA EXTRA | B33: =EZEQUIEL!I10 -> 8358.13 | C33: =EZEQUIEL!J10 -> 13 | D33: =EZEQUIEL!K10 -> 108655.69 | F33: ='JOSE '!H10 -> 1ra QUINCENA | G33: ='JOSE '!I10 -> 900000 | H33: ='JOSE '!J10 -> 1 | I33: ='JOSE '!K10 -> 900000 | K33: CATEGORIA | L33: =WALTER!I12 -> 35000 | M33: =WALTER!J12 -> 1 | N33: =WALTER!K12 -> 35000
A34: VIATICOS | B34: =EZEQUIEL!I11 -> 6000 | C34: =EZEQUIEL!J11 -> 9 | D34: =EZEQUIEL!K11 -> 54000 | I34: 0 | K34: =WALTER!H13 -> 0 | L34: =WALTER!I13 -> 0 | M34: =WALTER!J13 -> 0 | N34: =WALTER!K13 -> 0
A35: PREMIO | B35: =EZEQUIEL!I12 -> 10447.64 | C35: =EZEQUIEL!J12 -> 10 | D35: =EZEQUIEL!K12 -> 104476.4 | H35: =RENZO!J12 -> 0 | I35: =RENZO!K12 -> 0 | K35: Total | N35: =SUBTOTAL(109,Tabla2314111448[SUB TOTAL]) -> 891000
C36: =EZEQUIEL!J13 -> 0 | D36: =EZEQUIEL!K13 -> 0 | F36: Total | I36: =Tabla231411141618231159[[#Totals],[SUB TOTAL]] -> 900000 | K36: DESCUENTOS
A37: Total | D37: =Tabla23141114161823[[#Totals],[SUB TOTAL]] -> 672132.09 | F37: DESCUENTOS | K37: FECHA | L37: CONCEPTO | M37: CANTIDAD | N37: TOTAL
A38: DESCUENTOS | F38: FECHA | G38: CONCEPTO | H38: CANTIDAD | I38: TOTAL | K38: 44670 | L38: ADELANTO | M38: 150000 | N38: =WALTER!K17 -> 741000
A39: FECHA | B39: CONCEPTO | C39: CANTIDAD | D39: TOTAL | F39: 44670 | G39: ADELANTO | H39: 500000 | I39: ='JOSE '!K17 -> 400000 | M39: =WALTER!J18 -> 0 | N39: =WALTER!K18 -> 741000
A40: 44670 | B40: ADELANTO | C40: 60000 | D40: =EZEQUIEL!K17 -> 672132.09 | H40: 0 | I40: ='JOSE '!K18 -> 400000 | M40: =WALTER!J19 -> 0 | N40: =WALTER!K19 -> 741000
C41: =EZEQUIEL!J18 -> 0 | D41: =EZEQUIEL!K18 -> 672132.09 | H41: 0 | I41: ='JOSE '!K19 -> 400000 | K41: FIRMA CONFORME _____________________
C42: =EZEQUIEL!J19 -> 0 | D42: =EZEQUIEL!K19 -> 672132.09
A43: FIRMA CONFORME _____________________
F54: DETALLE DE QUINCENA
A56: DETALLE DE QUINCENA | F56: NOMBRE: | G56: =ISAIAS!I6 -> ISAIAS | H56: FECHA: | I56: =ISAIAS!K6 -> 44716 | K56: DETALLE DE QUINCENA
F57: CONCEPTO | G57: VALOR | H57: CANTIDAD | I57: SUB TOTAL
...

Sheet Vacaciones aguinaldo
A1: DETALLE | F1: DETALLE
A3: NOMBRE: | B3: LEO | C3: FECHA: | D3: =TODAY() -> 44716 | F3: NOMBRE: | G3: GABRIEL | H3: FECHA: | I3: =TODAY() -> 44716
A4: CONCEPTO | B4: VALOR | C4: CANTIDAD | D4: SUB TOTAL | F4: CONCEPTO | G4: VALOR | H4: CANTIDAD | I4: SUB TOTAL
A5: VACACIONES | B5: 4000 | C5: 14 | D5: =Tabla2314111416182356444695[[#This Row],[VALOR]]*Tabla2314111416182356444695[[#This Row],[CANTIDAD]] -> 56000 | F5: VACACIONES | G5: 4000 | H5: 14 | I5: =Tabla231411141618235644469575[[#This Row],[VALOR]]*Tabla231411141618235644469575[[#This Row],[CANTIDAD]] -> 56000
A6: AGUINALDOS | B6: 263410 | C6: 1 | D6: =Tabla2314111416182356444695[[#This Row],[VALOR]]*Tabla2314111416182356444695[[#This Row],[CANTIDAD]] -> 263410 | F6: AGUINALDOS | G6: 220100 | H6: 1 | I6: =Tabla231411141618235644469575[[#This Row],[VALOR]]*Tabla231411141618235644469575[[#This Row],[CANTIDAD]] -> 220100
C7: TOTAL | D7: =D5+D6 -> 319410 | H7: TOTAL | I7: =I5+I6 -> 276100
A8: DESCUENTOS | F8: DESCUENTOS
A9: FECHA | B9: CONCEPTO | C9: CANTIDAD | D9: TOTAL | F9: FECHA | G9: CONCEPTO | H9: CANTIDAD | I9: TOTAL
A10: 44548 | B10: ADELANTO | C10: 200000 | D10: =Tabla2314111416182356444695[[#Totals],[SUB TOTAL]]-Tabla33210131517192557454796[[#This Row],[CANTIDAD]] -> 119410 | I10: =Tabla231411141618235644469575[[#Totals],[SUB TOTAL]]-Tabla3321013151719255745479676[[#This Row],[CANTIDAD]] -> 276100
D11: =D10-Tabla33210131517192557454796[[#This Row],[CANTIDAD]] -> 119410 | I11: =I10-Tabla3321013151719255745479676[[#This Row],[CANTIDAD]] -> 276100
B12: TOTAL | C12: A PAGAR | D12: =D11 -> 119410 | G12: TOTAL | H12: A PAGAR | I12: =I11 -> 276100
A14: DETALLE | F14: DETALLE
A16: NOMBRE: | B16: CESAR | C16: FECHA: | D16: =TODAY() -> 44716 | F16: NOMBRE: | G16: DARIO | H16: FECHA: | I16: =TODAY() -> 44716
A17: CONCEPTO | B17: VALOR | C17: CANTIDAD | D17: SUB TOTAL | F17: CONCEPTO | G17: VALOR | H17: CANTIDAD | I17: SUB TOTAL
D18: =Tabla2314111416182356444695102[[#This Row],[VALOR]]*Tabla2314111416182356444695102[[#This Row],[CANTIDAD]] -> 0 | F18: VACACIONES | G18: 31500 | H18: 14 | I18: =Tabla231411141618235644469575104[[#This Row],[VALOR]]*Tabla231411141618235644469575104[[#This Row],[CANTIDAD]] -> 441000
A19: AGUINALDOS | B19: 115000 | C19: 1 | D19: =Tabla2314111416182356444695102[[#This Row],[VALOR]]*Tabla2314111416182356444695102[[#This Row],[CANTIDAD]] -> 115000 | F19: AGUINALDOS | G19: 525000 | H19: 1 | I19: =Tabla231411141618235644469575104[[#This Row],[VALOR]]*Tabla231411141618235644469575104[[#This Row],[CANTIDAD]] -> 525000
C20: TOTAL | D20: =D18+D19 -> 115000 | H20: TOTAL | I20: =I18+I19 -> 966000
A21: DESCUENTOS | F21: DESCUENTOS
A22: FECHA | B22: CONCEPTO | C22: CANTIDAD | D22: TOTAL | F22: FECHA | G22: CONCEPTO | H22: CANTIDAD | I22: TOTAL
D23: =Tabla2314111416182356444695102[[#Totals],[SUB TOTAL]]-Tabla33210131517192557454796103[[#This Row],[CANTIDAD]] -> 115000 | I23: =Tabla231411141618235644469575104[[#Totals],[SUB TOTAL]]-Tabla3321013151719255745479676105[[#This Row],[CANTIDAD]] -> 966000
D24: =D23-Tabla33210131517192557454796103[[#This Row],[CANTIDAD]] -> 115000 | I24: =I23-Tabla3321013151719255745479676105[[#This Row],[CANTIDAD]] -> 966000
B25: TOTAL | C25: A PAGAR | D25: =D24 -> 115000 | G25: TOTAL | H25: A PAGAR | I25: =I24 -> 966000
A27: DETALLE | F27: DETALLE
A29: NOMBRE: | B29: FRANCISCO | C29: FECHA: | D29: =TODAY() -> 44716 | F29: NOMBRE: | G29: ISAIAS | H29: FECHA: | I29: =TODAY() -> 44716
A30: CONCEPTO | B30: VALOR | C30: CANTIDAD | D30: SUB TOTAL | F30: CONCEPTO | G30: VALOR | H30: CANTIDAD | I30: SUB TOTAL
A31: VACACIONES | B31: 31500 | C31: 14 | D31: =Tabla231411141618235644469510279[[#This Row],[VALOR]]*Tabla231411141618235644469510279[[#This Row],[CANTIDAD]] -> 441000 | F31: VACACIONES | G31: 36000 | H31: 14 | I31: =Tabla23141114161823564446957510481[[#This Row],[VALOR]]*Tabla23141114161823564446957510481[[#This Row],[CANTIDAD]] -> 504000
A32: AGUINALDOS | B32: 400000 | C32: 1 | D32: =Tabla231411141618235644469510279[[#This Row],[VALOR]]*Tabla231411141618235644469510279[[#This Row],[CANTIDAD]] -> 400000 | F32: AGUINALDOS | G32: 540000 | H32: 1 | I32: =Tabla23141114161823564446957510481[[#This Row],[VALOR]]*Tabla23141114161823564446957510481[[#This Row],[CANTIDAD]] -> 540000
C33: TOTAL | D33: =D31+D32 -> 841000 | H33: TOTAL | I33: =I31+I32 -> 1044000
A34: DESCUENTOS | F34: DESCUENTOS
A35: FECHA | B35: CONCEPTO | C35: CANTIDAD | D35: TOTAL | F35: FECHA | G35: CONCEPTO | H35: CANTIDAD | I35: TOTAL
D36: =Tabla231411141618235644469510279[[#Totals],[SUB TOTAL]]-Tabla3321013151719255745479610380[[#This Row],[CANTIDAD]] -> 841000 | I36: =Tabla23141114161823564446957510481[[#Totals],[SUB TOTAL]]-Tabla332101315171925574547967610582[[#This Row],[CANTIDAD]] -> 1044000
D37: =D36-Tabla3321013151719255745479610380[[#This Row],[CANTIDAD]] -> 841000 | I37: =I36-Tabla332101315171925574547967610582[[#This Row],[CANTIDAD]] -> 1044000
B38: TOTAL | C38: A PAGAR | D38: =D37 -> 841000 | G38: TOTAL | H38: A PAGAR | I38: =I37 -> 1044000
A40: DETALLE | F40: DETALLE
A42: NOMBRE: | B42: ALAN | C42: FECHA: | D42: =TODAY() -> 44716 | F42: NOMBRE: | G42: DANIEL | H42: FECHA: | I42: =TODAY() -> 44716
A43: CONCEPTO | B43: VALOR | C43: CANTIDAD | D43: SUB TOTAL | F43: CONCEPTO | G43: VALOR | H43: CANTIDAD | I43: SUB TOTAL
A44: VACACIONES | B44: 33300 | C44: 1 | D44: =Tabla231411141618235644469510285[[#This Row],[VALOR]]*Tabla231411141618235644469510285[[#This Row],[CANTIDAD]] -> 33300 | F44: VACACIONES | G44: 36000 | H44: 14 | I44: =Tabla23141114161823564446951028578[[#This Row],[VALOR]]*Tabla23141114161823564446951028578[[#This Row],[CANTIDAD]] -> 504000
A45: AGUINALDOS | B45: 140000 | C45: 1 | D45: =Tabla231411141618235644469510285[[#This Row],[VALOR]]*Tabla231411141618235644469510285[[#This Row],[CANTIDAD]] -> 140000 | F45: AGUINALDOS | G45: 610000 | H45: 1 | I45: =Tabla23141114161823564446951028578[[#This Row],[VALOR]]*Tabla23141114161823564446951028578[[#This Row],[CANTIDAD]] -> 610000
C46: TOTAL | D46: =D44+D45 -> 173300 | H46: TOTAL | I46: =I44+I45 -> 1114000
A47: DESCUENTOS | F47: DESCUENTOS
...

Sheet Hoja1
A1: DETALLE | F1: DETALLE
A3: NOMBRE: | B3: BERTHA | C3: FECHA: | D3: =TODAY() -> 44716 | F3: NOMBRE: | G3: ROBERTO | H3: FECHA: | I3: =TODAY() -> 44716
A4: CONCEPTO | B4: VALOR | C4: CANTIDAD | D4: SUB TOTAL | F4: CONCEPTO | G4: VALOR | H4: CANTIDAD | I4: SUB TOTAL
A5: VACACIONES | B5: 52000 | C5: 14 | D5: 378000 | F5: VACACIONES | G5: 48000 | H5: 14 | I5: =Tabla2314111416182356444695751048193[[#This Row],[VALOR]]*Tabla2314111416182356444695751048193[[#This Row],[CANTIDAD]] -> 672000
A6: AGUINALDOS | B6: 650000 | C6: 1 | D6: =Tabla23141114161823564446951027991[[#This Row],[VALOR]]*Tabla23141114161823564446951027991[[#This Row],[CANTIDAD]] -> 650000 | F6: AGUINALDOS | G6: 600000 | H6: 1 | I6: =Tabla2314111416182356444695751048193[[#This Row],[VALOR]]*Tabla2314111416182356444695751048193[[#This Row],[CANTIDAD]] -> 600000
A7: SUELDO | B7: 650000 | C7: 1 | D7: =Tabla23141114161823564446951027991[[#This Row],[VALOR]]*Tabla23141114161823564446951027991[[#This Row],[CANTIDAD]] -> 650000 | F7: SUELDO | G7: 600000 | H7: 1 | I7: =Tabla2314111416182356444695751048193[[#This Row],[VALOR]]*Tabla2314111416182356444695751048193[[#This Row],[CANTIDAD]] -> 600000
C8: TOTAL | D8: =D5+D6+D7 -> 1678000 | H8: TOTAL | I8: =I5+I6+I7 -> 1872000
A9: DESCUENTOS | F9: DESCUENTOS
A10: FECHA | B10: CONCEPTO | C10: CANTIDAD | D10: TOTAL | F10: FECHA | G10: CONCEPTO | H10: CANTIDAD | I10: TOTAL
D11: =Tabla23141114161823564446951027991[[#Totals],[SUB TOTAL]]-Tabla332101315171925574547961038092[[#This Row],[CANTIDAD]] -> 1678000 | I11: =Tabla2314111416182356444695751048193[[#Totals],[SUB TOTAL]]-Tabla33210131517192557454796761058294[[#This Row],[CANTIDAD]] -> 1872000
D12: =D11-Tabla332101315171925574547961038092[[#This Row],[CANTIDAD]] -> 1678000 | I12: =I11-Tabla33210131517192557454796761058294[[#This Row],[CANTIDAD]] -> 1872000
B13: TOTAL | C13: A PAGAR | D13: =D12 -> 1678000 | G13: TOTAL | H13: A PAGAR | I13: =I12 -> 1872000
I17: =D13+I13 -> 3550000

Sheet Hoja5

Sheet Hoja2
A1: DETALLE
A3: NOMBRE: | B3: LEO SOTO | C3: FECHA: | D3: =TODAY() -> 44716
A4: CONCEPTO | B4: VALOR X DIA | C4: CANTIDAD | D4: SUB TOTAL
A5: VACACIONES | B5: 30300 | C5: 7 | D5: =Tabla231411141618235644469561[[#This Row],[VALOR X DIA]]*Tabla231411141618235644469561[[#This Row],[CANTIDAD]] -> 212100
D6: =Tabla231411141618235644469561[[#This Row],[VALOR X DIA]]*Tabla231411141618235644469561[[#This Row],[CANTIDAD]] -> 0
C7: TOTAL | D7: =D5+D6 -> 212100
A8: DESCUENTOS
A9: FECHA | B9: CONCEPTO | C9: CANTIDAD | D9: TOTAL
A12: CONFORME | B12: FIRMA
A18: DETALLE
A20: NOMBRE: | B20: LEO SOTO | C20: FECHA: | D20: =TODAY() -> 44716
A21: CONCEPTO | B21: VALOR X DIA | C21: CANTIDAD | D21: SUB TOTAL
A22: VACACIONES | B22: 30300 | C22: 7 | D22: =Tabla23141114161823564446956166[[#This Row],[VALOR X DIA]]*Tabla23141114161823564446956166[[#This Row],[CANTIDAD]] -> 212100
D23: =Tabla23141114161823564446956166[[#This Row],[VALOR X DIA]]*Tabla23141114161823564446956166[[#This Row],[CANTIDAD]] -> 0
C24: TOTAL | D24: =D22+D23 -> 212100
A25: DESCUENTOS
A26: FECHA | B26: CONCEPTO | C26: CANTIDAD | D26: TOTAL
A29: CONFORME | B29: FIRMA

Sheet Hoja3
A2: DICIEMBRE | B2: 1ra Q | D2: DICIEM | E2: 2da Q
A4: LEO
A5: GABRIEL
A6: DANIEL
A7: ISAIAS
A8: MIGUEL
A9: DARIO
A10: ALAN
A11: WALTER
A12: CESAR
A13: EZEQUIEL
A16: ENER | B16: 1ra Q | D16: ENER | E16: 2da Q | F16: FEBR | G16: 1ra Q | I16: FEBR | J16: 2da Q | K16: MARZ | L16: 1ra Q | N16: MARZ | O16: 2da Q
A18: LEO | F18: LEO | K18: LEO
A19: GABRIEL | F19: GABRIEL | K19: GABRIEL
A20: DANIEL | F20: DANIEL | K20: DANIEL
A21: ISAIAS | F21: ISAIAS | K21: ISAIAS
A22: MIGUEL | F22: MIGUEL | K22: MIGUEL
A23: DARIO | F23: DARIO | K23: DARIO
A24: ALAN | F24: ALAN | K24: ALAN
A25: WALTER | F25: WALTER | K25: WALTER
A26: CESAR | F26: CESAR | K26: CESAR
A27: EZEQUIEL | F27: EZEQUIEL | K27: EZEQUIEL

Sheet Hoja4
A4: DETALLE DE QUINCENA
A6: NOMBRE: | B6: JOSE | C6: FECHA: | D6: =TODAY() -> 44716
A7: CONCEPTO | B7: VALOR | C7: CANTIDAD | D7: SUB TOTAL
A8: MES DE ABRIL | B8: 1800000 | D8: =Tabla23141114161823115997[[#This Row],[VALOR]]*Tabla23141114161823115997[[#This Row],[CANTIDAD]] -> 0
A9: 1ra QUINCENA | B9: 900000 | C9: 1 | D9: =Tabla23141114161823115997[[#This Row],[VALOR]]*Tabla23141114161823115997[[#This Row],[CANTIDAD]] -> 900000
D10: =Tabla23141114161823115997[[#This Row],[VALOR]]*Tabla23141114161823115997[[#This Row],[CANTIDAD]] -> 0
